Workbook

Sheet Indicator Master
A1: Credit Monitoring — Indicator Master
A3: UID | B3: Module | C3: Indicator | D3: Description | E3: Category | F3: Critical (Yes/No) | G3: What to Track (Input) | H3: Data Source Channel | I3: Acquisition Mechanism | J3: Data Type | K3: Update Frequency | L3: Functional Calculation Formula | M3: Threshold & Score | N3: Max Score
A4: CM-001 | B4: Credit Monitoring | C4: DPD (days past due) | D4: Delay in interest payment | E4: Account Conduct | F4: No | G4: EMI / interest overdue by 1-30 days | H4: Bank Core System (CBS) | I4: Direct CBS extract | J4: Quantitative | K4: Daily | L4: MAX days past due across facilities as of run date | M4: 0 days = 0 | 1-30 DPD = 10 | 31-60 DPD = 20 | 61-90 DPD = 30 | 90+ DPD = 40 | N4: 40
A5: CM-002 | B5: Credit Monitoring | C5: Excess over DP/limit % | D5: Overdrawing beyond sanctioned limit | E5: Account Conduct | F5: No | G5: Drawing power breach or limit excess | H5: Bank Core System (CBS) | I5: Direct CBS extract | J5: Quantitative | K5: Daily | L5: Excess% = (Outstanding - DrawingPower)/DrawingPower | M5: No breach = 0 | Up to 5% breach = 10 | 5-10% = 20 | >10% or repeated = 30 | N5: 30
A6: CM-003 | B6: Credit Monitoring | C6: GST turnover change % / vs bank credits | D6: Decline in GST turnover | E6: Financial Performance | F6: No | G6: GST sales lower than projected or lower than bank statement credits | H6: External API | I6: GST portal / GSTN API (with consent) | J6: Quantitative | K6: Monthly | L6: GSTChange% vs prior period; and GST vs bank credits | M6: Stable/increasing = 0 | 10-20% decline = 10 | 20-40% decline = 20 | >40% decline = 35 | N6: 35
A7: CM-004 | B7: Credit Monitoring | C7: Cash Flow from Operations (sign / periods) | D7: Negative cash flow from operations | E7: Financial Performance | F7: No | G7: CFO negative for repeated periods | H7: Bank-provided Financial Statements | I7: Audited financials / CMA | J7: Quantitative | K7: Quarterly | L7: Sign(CFO) & count of consecutive negative periods | M7: Positive CFO = 0 | 1 negative period = 15 | 2 consecutive periods = 30 | ≥3 consecutive period or severe negative = 40 | N7: 40
A8: CM-005 | B8: Credit Monitoring | C8: Current Ratio | D8: Weak current ratio | E8: Financial Performance | F8: No | G8: Current assets lower compared to current liabilities | H8: Bank-provided Financial Statements | I8: Audited financials / CMA | J8: Quantitative | K8: Quarterly | L8: Compute Current Ratio then compare to threshold bands | M8: >=1.33 = 0 | 1.10-1.32 = 10 | 1.00-1.09 = 20 | <1.00 = 35 | N8: 35
A9: CM-006 | B9: Credit Monitoring | C9: Audit opinion classification | D9: Adverse audit remarks | E9: Audit | F9: No | G9: Qualified audit opinion or going concern issue | H9: External + Internal Docs | I9: Audited financials and Ministry of Corporate Affairs (MCA) filings | J9: Qualitative | K9: Annual | L9: Classify event severity for 'Adverse audit remarks' (no numeric calc) | M9: No issue = 0 | delayed/minor qualification = 10 | material qualification/change = 25 | going concern/adverse = 40 | N9: 40
A10: CM-007 | B10: Credit Monitoring | C10: NCLT/IBC admission status | D10: NCLT/IBC proceedings | E10: Insolvency | F10: No | G10: Insolvency filing against borrower or group | H10: External (Legal DB) | I10: Court/NCLT DB or paid aggregator | J10: Qualitative | K10: Event | L10: NCLT/IBC admission = TRUE/FALSE | M10: No case = 0 | civil/regulatory notice = 15 | multiple/material cases = 30 | IBC/NCLT = 50 | N10: 50
A11: CM-008 | B11: Credit Monitoring | C11: Restructuring request status | D11: Frequent restructuring requests | E11: Credit Risk | F11: No | G11: Moratorium, repayment extension, lower interest request | H11: External + Internal Docs | I11: Map in data discovery | J11: Qualitative | K11: Event | L11: Check restructuring request status | M11: No request = 0 | informal request = 15 | formal restructuring = 30 | repeated = 40 | N11: 40
A12: CM-009 | B12: Credit Monitoring | C12: Security/collateral cover ratio | D12: Reduction in security cover | E12: Collateral Risk | F12: No | G12: Collateral value falling | H12: Internal Tracker | I12: Collateral register + valuer | J12: Quantitative | K12: Quarterly | L12: Compute Security/collateral cover ratio then compare to threshold bands | M12: ≥1.25 (adequate) = 0 | 1.10–1.25 (minor shortfall) = 15 | 1.00–1.10 (major shortfall) = 30 | <1.00 (under-secured) = 40 | N12: 40
A13: CM-010 | B13: Credit Monitoring | C13: Insurance validity / days to expiry | D13: Insurance policy expiry | E13: Collateral Risk | F13: No | G13: Stock/property/machinery insurance not renewed | H13: Internal Tracker | I13: Collateral/insurance register + valuer | J13: Qualitative | K13: Event | L13: DaysToExpiry(insurance); lapsed = TRUE/FALSE | M13: Adequate/current = 0 | minor shortfall/lapse = 15 | major shortfall/lapse = 30 | uninsured/under-secured = 40 | N13: 40
A14: CM-011 | B14: Credit Monitoring | C14: Top-customer revenue concentration % | D14: Concentration of customers | E14: Business Risk | F14: No | G14: High sales from one or few customers | H14: Bank Core System (CBS) + Financials Statement | I14: Map in data discovery | J14: Quantitative | K14: Annual | L14: Compute Top-customer revenue concentration % then compare to threshold bands | M14: <25% exposure = 0 | 25-40% = 10 | 40-60% = 20 | >60% = 30 | N14: 30
A15: CM-012 | B15: Credit Monitoring | C15: Top-supplier purchase concentration % | D15: Concentration of suppliers | E15: Business Risk | F15: No | G15: Dependence on few suppliers | H15: Bank Core System (CBS) + Financials Statement | I15: Map in data discovery | J15: Quantitative | K15: Annual | L15: Compute Top-supplier purchase concentration % then compare to threshold bands | M15: <25% exposure = 0 | 25-40% = 10 | 40-60% = 20 | >60% = 30 | N15: 30
... A24: CM-021 | B24: Credit Monitoring | C24: Count of overdue events (rolling 3-6m) | D24: Frequent overdues | E24: Account Conduct | F24: No | G24: Number of times borrower delays payment in last 3-6 months | H24: Bank Core System (CBS) | I24: Direct CBS extract | J24: Quantitative | K24: Daily | L24: COUNT(overdue events) in rolling 3-6 months | M24: 0 instances = 0 | 1 instance = 5 | 2 instances = 15 | 3+ instances = 25 | N24: 25

Sheet Functional Logic
A1: Functional Logic (per indicator)
A2: Input → Calculation/Classification → Threshold Evaluation → Raw Score → Normalised Score. Max Score links to the Master.
A4: UID | B4: Indicator | C4: Module | D4: Step 1 — Input (What to Track) | E4: Step 2 — Calculation / Classification | F4: Step 3 — Threshold Evaluation (bands) | G4: Max Score | H4: Step 4 — Raw Score rule | I4: Step 5 — Normalised Score
A5: CM-001 | B5: DPD (days past due) | C5: Credit Monitoring | D5: EMI / interest overdue by 1-30 days | E5: MAX days past due across facilities as of run date | F5: 0 days = 0 | 1-30 DPD = 10 | 31-60 DPD = 20 | 61-90 DPD = 30 | 90+ DPD = 40 | G5: =INDEX('Indicator Master'!$N$4:$N$24,MATCH($A5,'Indicator Master'!$A$4:$A$24,0)) -> 40 | H5: Raw Score = score of the single band whose condition the borrower value satisfies; 0 if none is breached. | I5: Normalised = Raw ÷ Max Score × 100 (0–100). Fed into the Overall Score Engine.
A6: CM-002 | B6: Excess over DP/limit % | C6: Credit Monitoring | D6: Drawing power breach or limit excess | E6: Excess% = (Outstanding - DrawingPower)/DrawingPower | F6: No breach = 0 | Up to 5% breach = 10 | 5-10% = 20 | >10% or repeated = 30 | G6: =INDEX('Indicator Master'!$N$4:$N$24,MATCH($A6,'Indicator Master'!$A$4:$A$24,0)) -> 30 | H6: Raw Score = score of the single band whose condition the borrower value satisfies; 0 if none is breached. | I6: Normalised = Raw ÷ Max Score × 100 (0–100). Fed into the Overall Score Engine.
A7: CM-003 | B7: GST turnover change % / vs bank credits | C7: Credit Monitoring | D7: GST sales lower than projected or lower than bank statement credits | E7: GSTChange% vs prior period; and GST vs bank credits | F7: Stable/increasing = 0 | 10-20% decline = 10 | 20-40% decline = 20 | >40% decline = 35 | G7: =INDEX('Indicator Master'!$N$4:$N$24,MATCH($A7,'Indicator Master'!$A$4:$A$24,0)) -> 35 | H7: Raw Score = score of the single band whose condition the borrower value satisfies; 0 if none is breached. | I7: Normalised = Raw ÷ Max Score × 100 (0–100). Fed into the Overall Score Engine.
A8: CM-004 | B8: Cash Flow from Operations (sign / periods) | C8: Credit Monitoring | D8: CFO negative for repeated periods | E8: Sign(CFO) & count of consecutive negative periods | F8: Positive CFO = 0 | 1 negative period = 15 | 2 consecutive periods = 30 | ≥3 consecutive period or severe negative = 40 | G8: =INDEX('Indicator Master'!$N$4:$N$24,MATCH($A8,'Indicator Master'!$A$4:$A$24,0)) -> 40 | H8: Raw Score = score of the single band whose condition the borrower value satisfies; 0 if none is breached. | I8: Normalised = Raw ÷ Max Score × 100 (0–100). Fed into the Overall Score Engine.
A9: CM-005 | B9: Current Ratio | C9: Credit Monitoring | D9: Current assets lower compared to current liabilities | E9: Compute Current Ratio then compare to threshold bands | F9: >=1.33 = 0 | 1.10-1.32 = 10 | 1.00-1.09 = 20 | <1.00 = 35 | G9: =INDEX('Indicator Master'!$N$4:$N$24,MATCH($A9,'Indicator Master'!$A$4:$A$24,0)) -> 35 | H9: Raw Score = score of the single band whose condition the borrower value satisfies; 0 if none is breached. | I9: Normalised = Raw ÷ Max Score × 100 (0–100). Fed into the Overall Score Engine.
A10: CM-006 | B10: Audit opinion classification | C10: Credit Monitoring | D10: Qualified audit opinion or going concern issue | E10: Classify event severity for 'Adverse audit remarks' (no numeric calc) | F10: No issue = 0 | delayed/minor qualification = 10 | material qualification/change = 25 | going concern/adverse = 40 | G10: =INDEX('Indicator Master'!$N$4:$N$24,MATCH($A10,'Indicator Master'!$A$4:$A$24,0)) -> 40 | H10: Raw Score = score of the single band whose condition the borrower value satisfies; 0 if none is breached. | I10: Normalised = Raw ÷ Max Score × 100 (0–100). Fed into the Overall Score Engine.
A11: CM-007 | B11: NCLT/IBC admission status | C11: Credit Monitoring | D11: Insolvency filing against borrower or group | E11: NCLT/IBC admission = TRUE/FALSE | F11: No case = 0 | civil/regulatory notice = 15 | multiple/material cases = 30 | IBC/NCLT = 50 | G11: =INDEX('Indicator Master'!$N$4:$N$24,MATCH($A11,'Indicator Master'!$A$4:$A$24,0)) -> 50 | H11: Raw Score = score of the single band whose condition the borrower value satisfies; 0 if none is breached. | I11: Normalised = Raw ÷ Max Score × 100 (0–100). Fed into the Overall Score Engine.
A12: CM-008 | B12: Restructuring request status | C12: Credit Monitoring | D12: Moratorium, repayment extension, lower interest request | E12: Check restructuring request status | F12: No request = 0 | informal request = 15 | formal restructuring = 30 | repeated = 40 | G12: =INDEX('Indicator Master'!$N$4:$N$24,MATCH($A12,'Indicator Master'!$A$4:$A$24,0)) -> 40 | H12: Raw Score = score of the single band whose condition the borrower value satisfies; 0 if none is breached. | I12: Normalised = Raw ÷ Max Score × 100 (0–100). Fed into the Overall Score Engine.
A13: CM-009 | B13: Security/collateral cover ratio | C13: Credit Monitoring | D13: Collateral value falling | E13: Compute Security/collateral cover ratio then compare to threshold bands | F13: ≥1.25 (adequate) = 0 | 1.10–1.25 (minor shortfall) = 15 | 1.00–1.10 (major shortfall) = 30 | <1.00 (under-secured) = 40 | G13: =INDEX('Indicator Master'!$N$4:$N$24,MATCH($A13,'Indicator Master'!$A$4:$A$24,0)) -> 40 | H13: Raw Score = score of the single band whose condition the borrower value satisfies; 0 if none is breached. | I13: Normalised = Raw ÷ Max Score × 100 (0–100). Fed into the Overall Score Engine.
A14: CM-010 | B14: Insurance validity / days to expiry | C14: Credit Monitoring | D14: Stock/property/machinery insurance not renewed | E14: DaysToExpiry(insurance); lapsed = TRUE/FALSE | F14: Adequate/current = 0 | minor shortfall/lapse = 15 | major shortfall/lapse = 30 | uninsured/under-secured = 40 | G14: =INDEX('Indicator Master'!$N$4:$N$24,MATCH($A14,'Indicator Master'!$A$4:$A$24,0)) -> 40 | H14: Raw Score = score of the single band whose condition the borrower value satisfies; 0 if none is breached. | I14: Normalised = Raw ÷ Max Score × 100 (0–100). Fed into the Overall Score Engine.
A15: CM-011 | B15: Top-customer revenue concentration % | C15: Credit Monitoring | D15: High sales from one or few customers | E15: Compute Top-customer revenue concentration % then compare to threshold bands | F15: <25% exposure = 0 | 25-40% = 10 | 40-60% = 20 | >60% = 30 | G15: =INDEX('Indicator Master'!$N$4:$N$24,MATCH($A15,'Indicator Master'!$A$4:$A$24,0)) -> 30 | H15: Raw Score = score of the single band whose condition the borrower value satisfies; 0 if none is breached. | I15: Normalised = Raw ÷ Max Score × 100 (0–100). Fed into the Overall Score Engine.
A16: CM-012 | B16: Top-supplier purchase concentration % | C16: Credit Monitoring | D16: Dependence on few suppliers | E16: Compute Top-supplier purchase concentration % then compare to threshold bands | F16: <25% exposure = 0 | 25-40% = 10 | 40-60% = 20 | >60% = 30 | G16: =INDEX('Indicator Master'!$N$4:$N$24,MATCH($A16,'Indicator Master'!$A$4:$A$24,0)) -> 30 | H16: Raw Score = score of the single band whose condition the borrower value satisfies; 0 if none is breached. | I16: Normalised = Raw ÷ Max Score × 100 (0–100). Fed into the Overall Score Engine.
... A25: CM-021 | B25: Count of overdue events (rolling 3-6m) | C25: Credit Monitoring | D25: Number of times borrower delays payment in last 3-6 months | E25: COUNT(overdue events) in rolling 3-6 months | F25: 0 instances = 0 | 1 instance = 5 | 2 instances = 15 | 3+ instances = 25 | G25: =INDEX('Indicator Master'!$N$4:$N$24,MATCH($A25,'Indicator Master'!$A$4:$A$24,0)) -> 25 | H25: Raw Score = score of the single band whose condition the borrower value satisfies; 0 if none is breached. | I25: Normalised = Raw ÷ Max Score × 100 (0–100). Fed into the Overall Score Engine.

Sheet Scoring Engine (Rules)
A1: Threshold & Scoring Engine — Machine-Readable Rules + Remedial Playbook
A2: One row per band. Rule Type/Lower/Upper/Operator are data-type driven; Normalised@Band & Is-Max are live; key = UID|Raw.
A4: UID | B4: Indicator | C4: Module | D4: Metric / Input | E4: Band Order | F4: Condition | G4: Rule Type | H4: Lower Bound | I4: Upper Bound | J4: Operator | K4: Raw Score | L4: Normalised @ Band | M4: Is Max Band | N4: Critical Event Flag | O4: What it signals & likely drivers | P4: Remedial action plan (step-by-step) | Q4: Primary owner | R4: key (helper)
A5: CM-001 | B5: DPD (days past due) | C5: Credit Monitoring | D5: EMI / interest overdue by 1-30 days | E5: 1 | F5: 0 days | G5: Count/Days Exact | H5: 0 | I5: 0 | J5: exactly = value | K5: 0 | L5: =$K5/INDEX('Indicator Master'!$N$4:$N$24,MATCH($A5,'Indicator Master'!$A$4:$A$24,0))*'Risk Bands (Config)'!$B$5 -> 0 | M5: =IF($K5=INDEX('Indicator Master'!$N$4:$N$24,MATCH($A5,'Indicator Master'!$A$4:$A$24,0)),1,0) -> 0 | O5: Normal — no days past due; servicing on time. | P5: No remedial action required. Continue routine monitoring at the standard review cycle and record the reading. | Q5: RM (routine) | R5: =$A5&"|"&$K5 -> CM-001|0
A6: CM-001 | B6: DPD (days past due) | C6: Credit Monitoring | D6: EMI / interest overdue by 1-30 days | E6: 2 | F6: 1-30 DPD | G6: Days Range | H6: 1 | I6: 30 | J6: ≥ lower & ≤ upper | K6: 10 | L6: =$K6/INDEX('Indicator Master'!$N$4:$N$24,MATCH($A6,'Indicator Master'!$A$4:$A$24,0))*'Risk Bands (Config)'!$B$5 -> 25 | M6: =IF($K6=INDEX('Indicator Master'!$N$4:$N$24,MATCH($A6,'Indicator Master'!$A$4:$A$24,0)),1,0) -> 0 | O6: Early warning — 1–30 days past due (SMA-0); a short cash-flow slip. | P6: 1) Contact the borrower; obtain the reason and a dated payment commitment. 2) Tag SMA-0. 3) Watch daily. | Q6: Relationship Manager (Branch) | R6: =$A6&"|"&$K6 -> CM-001|10
A7: CM-001 | B7: DPD (days past due) | C7: Credit Monitoring | D7: EMI / interest overdue by 1-30 days | E7: 3 | F7: 31-60 DPD | G7: Days Range | H7: 31 | I7: 60 | J7: ≥ lower & ≤ upper | K7: 20 | L7: =$K7/INDEX('Indicator Master'!$N$4:$N$24,MATCH($A7,'Indicator Master'!$A$4:$A$24,0))*'Risk Bands (Config)'!$B$5 -> 50 | M7: =IF($K7=INDEX('Indicator Master'!$N$4:$N$24,MATCH($A7,'Indicator Master'!$A$4:$A$24,0)),1,0) -> 0 | O7: Elevated concern — 31–60 days past due (SMA-1); persistent delay indicating liquidity stress. | P7: 1) Escalate follow-up; RM engagement. 2) Tag SMA-1; obtain a corrective plan. 3) Review limit conduct. | Q7: RM + Credit Analyst | R7: =$A7&"|"&$K7 -> CM-001|20
A8: CM-001 | B8: DPD (days past due) | C8: Credit Monitoring | D8: EMI / interest overdue by 1-30 days | E8: 4 | F8: 61-90 DPD | G8: Days Range | H8: 61 | I8: 90 | J8: ≥ lower & ≤ upper | K8: 30 | L8: =$K8/INDEX('Indicator Master'!$N$4:$N$24,MATCH($A8,'Indicator Master'!$A$4:$A$24,0))*'Risk Bands (Config)'!$B$5 -> 75 | M8: =IF($K8=INDEX('Indicator Master'!$N$4:$N$24,MATCH($A8,'Indicator Master'!$A$4:$A$24,0)),1,0) -> 0 | O8: High concern — 61–90 days past due (SMA-2); serious delinquency approaching NPA. | P8: 1) Tag SMA-2; issue a formal notice. 2) Assess security and recovery options. 3) Escalate to Credit; provisioning review. | Q8: Credit Committee / Zonal Credit | R8: =$A8&"|"&$K8 -> CM-001|30
A9: CM-001 | B9: DPD (days past due) | C9: Credit Monitoring | D9: EMI / interest overdue by 1-30 days | E9: 5 | F9: 90+ DPD | G9: Days Threshold | H9: 90 | J9: > lower | K9: 40 | L9: =$K9/INDEX('Indicator Master'!$N$4:$N$24,MATCH($A9,'Indicator Master'!$A$4:$A$24,0))*'Risk Bands (Config)'!$B$5 -> 100 | M9: =IF($K9=INDEX('Indicator Master'!$N$4:$N$24,MATCH($A9,'Indicator Master'!$A$4:$A$24,0)),1,0) -> 1 | O9: Severe / critical — 90+ days past due; NPA-level default. | P9: 1) Classify NPA per norms and provide. 2) Invoke recovery / SARFAESI as warranted. 3) Escalate to Credit Committee / Recovery. | Q9: Credit Head / Risk | R9: =$A9&"|"&$K9 -> CM-001|40
A10: CM-002 | B10: Excess over DP/limit % | C10: Credit Monitoring | D10: Drawing power breach or limit excess | E10: 1 | F10: No breach | G10: Percent Threshold | I10: 0 | J10: ≤ upper | K10: 0 | L10: =$K10/INDEX('Indicator Master'!$N$4:$N$24,MATCH($A10,'Indicator Master'!$A$4:$A$24,0))*'Risk Bands (Config)'!$B$5 -> 0 | M10: =IF($K10=INDEX('Indicator Master'!$N$4:$N$24,MATCH($A10,'Indicator Master'!$A$4:$A$24,0)),1,0) -> 0 | O10: Normal — outstanding within the sanctioned DP/limit. | P10: No remedial action required. Continue routine monitoring at the standard review cycle and record the reading. | Q10: RM (routine) | R10: =$A10&"|"&$K10 -> CM-002|0
A11: CM-002 | B11: Excess over DP/limit % | C11: Credit Monitoring | D11: Drawing power breach or limit excess | E11: 2 | F11: Up to 5% breach | G11: Percent Range | H11: 0 | I11: 5 | J11: > lower & ≤ upper | K11: 10 | L11: =$K11/INDEX('Indicator Master'!$N$4:$N$24,MATCH($A11,'Indicator Master'!$A$4:$A$24,0))*'Risk Bands (Config)'!$B$5 -> 33.333333 | M11: =IF($K11=INDEX('Indicator Master'!$N$4:$N$24,MATCH($A11,'Indicator Master'!$A$4:$A$24,0)),1,0) -> 0 | O11: Early warning — excess up to 5%; minor, likely a timing over-draw. | P11: 1) Regularise the excess promptly. 2) Ascertain the reason. 3) Allow no fresh excess. | Q11: RM + Credit Analyst | R11: =$A11&"|"&$K11 -> CM-002|10
A12: CM-002 | B12: Excess over DP/limit % | C12: Credit Monitoring | D12: Drawing power breach or limit excess | E12: 3 | F12: 5-10% | G12: Percent Range | H12: 5 | I12: 10 | J12: > lower & ≤ upper | K12: 20 | L12: =$K12/INDEX('Indicator Master'!$N$4:$N$24,MATCH($A12,'Indicator Master'!$A$4:$A$24,0))*'Risk Bands (Config)'!$B$5 -> 66.666667 | M12: =IF($K12=INDEX('Indicator Master'!$N$4:$N$24,MATCH($A12,'Indicator Master'!$A$4:$A$24,0)),1,0) -> 0 | O12: Elevated concern — excess 5–10%; recurring over-limit use — DP or limit pressure. | P12: 1) Review DP/limit adequacy vs turnover. 2) Restrict further drawals. 3) Monitor; flag to Credit. | Q12: Credit Committee / Zonal Credit | R12: =$A12&"|"&$K12 -> CM-002|20
A13: CM-002 | B13: Excess over DP/limit % | C13: Credit Monitoring | D13: Drawing power breach or limit excess | E13: 4 | F13: >10% or repeated | G13: Percent Threshold | H13: 10 | J13: > lower (or repeated breach) | K13: 30 | L13: =$K13/INDEX('Indicator Master'!$N$4:$N$24,MATCH($A13,'Indicator Master'!$A$4:$A$24,0))*'Risk Bands (Config)'!$B$5 -> 100 | M13: =IF($K13=INDEX('Indicator Master'!$N$4:$N$24,MATCH($A13,'Indicator Master'!$A$4:$A$24,0)),1,0) -> 1 | O13: Severe / critical — excess >10% or repeated breaches; persistent over-drawing / liquidity stress. | P13: 1) Freeze fresh drawals pending review. 2) Reassess limits and conduct; corrective plan. 3) Escalate to Credit. | Q13: Credit Head / Risk | R13: =$A13&"|"&$K13 -> CM-002|30
A14: CM-003 | B14: GST turnover change % / vs bank credits | C14: Credit Monitoring | D14: GST sales lower than projected or lower than bank statement credits | E14: 1 | F14: Stable/increasing | G14: Percent Threshold | I14: 10 | J14: < upper | K14: 0 | L14: =$K14/INDEX('Indicator Master'!$N$4:$N$24,MATCH($A14,'Indicator Master'!$A$4:$A$24,0))*'Risk Bands (Config)'!$B$5 -> 0 | M14: =IF($K14=INDEX('Indicator Master'!$N$4:$N$24,MATCH($A14,'Indicator Master'!$A$4:$A$24,0)),1,0) -> 0 | O14: Normal — GST turnover stable or rising; activity intact. | P14: No remedial action required. Continue routine monitoring at the standard review cycle and record the reading. | Q14: RM (routine) | R14: =$A14&"|"&$K14 -> CM-003|0
A15: CM-003 | B15: GST turnover change % / vs bank credits | C15: Credit Monitoring | D15: GST sales lower than projected or lower than bank statement credits | E15: 2 | F15: 10-20% decline | G15: Percent Range | H15: 10 | I15: 20 | J15: ≥ lower & < upper | K15: 10 | L15: =$K15/INDEX('Indicator Master'!$N$4:$N$24,MATCH($A15,'Indicator Master'!$A$4:$A$24,0))*'Risk Bands (Config)'!$B$5 -> 28.571429 | M15: =IF($K15=INDEX('Indicator Master'!$N$4:$N$24,MATCH($A15,'Indicator Master'!$A$4:$A$24,0)),1,0) -> 0 | O15: Early warning — GST turnover down 10–20%; early softening or partial under-reporting. | P15: 1) Reconcile GST vs book sales vs bank credits. 2) Obtain the reason. 3) Monitor monthly. | Q15: Relationship Manager (Branch) | R15: =$A15&"|"&$K15 -> CM-003|10
A16: CM-003 | B16: GST turnover change % / vs bank credits | C16: Credit Monitoring | D16: GST sales lower than projected or lower than bank statement credits | E16: 3 | F16: 20-40% decline | G16: Percent Range | H16: 20 | I16: 40 | J16: ≥ lower & < upper | K16: 20 | L16: =$K16/INDEX('Indicator Master'!$N$4:$N$24,MATCH($A16,'Indicator Master'!$A$4:$A$24,0))*'Risk Bands (Config)'!$B$5 -> 57.142857 | M16: =IF($K16=INDEX('Indicator Master'!$N$4:$N$24,MATCH($A16,'Indicator Master'!$A$4:$A$24,0)),1,0) -> 0 | O16: Elevated concern — down 20–40%; material fall — demand loss or diversion of billing. | P16: 1) Reassess WC and projections. 2) Investigate under-reporting/diversion. 3) Enhanced monitoring; flag to Credit. | Q16: RM + Credit Analyst | R16: =$A16&"|"&$K16 -> CM-003|20
A17: CM-003 | B17: GST turnover change % / vs bank credits | C17: Credit Monitoring | D17: GST sales lower than projected or lower than bank statement credits | E17: 4 | F17: >40% decline | G17: Percent Threshold | H17: 40 | J17: ≥ lower | K17: 35 | L17: =$K17/INDEX('Indicator Master'!$N$4:$N$24,MATCH($A17,'Indicator Master'!$A$4:$A$24,0))*'Risk Bands (Config)'!$B$5 -> 100 | M17: =IF($K17=INDEX('Indicator Master'!$N$4:$N$24,MATCH($A17,'Indicator Master'!$A$4:$A$24,0)),1,0) -> 1 | O17: Severe / critical — down >40%; severe — sharp contraction or suppressed reporting. | P17: 1) Full turnover/viability review; verify against e-way bills/returns. 2) Corrective plan. 3) Escalate to Credit. | Q17: Credit Head / Risk | R17: =$A17&"|"&$K17 -> CM-003|35
A18: CM-004 | B18: Cash Flow from Operations (sign / periods) | C18: Credit Monitoring | D18: CFO negative for repeated periods | E18: 1 | F18: Positive CFO | G18: Count Exact | H18: 0 | I18: 0 | J18: exactly = value (positive CFO) | K18: 0 | L18: =$K18/INDEX('Indicator Master'!$N$4:$N$24,MATCH($A18,'Indicator Master'!$A$4:$A$24,0))*'Risk Bands (Config)'!$B$5 -> 0 | M18: =IF($K18=INDEX('Indicator Master'!$N$4:$N$24,MATCH($A18,'Indicator Master'!$A$4:$A$24,0)),1,0) -> 0 | O18: Normal — operating cash flow positive; self-funding operations. | P18: No remedial action required. Continue routine monitoring at the standard review cycle and record the reading. | Q18: RM (routine) | R18: =$A18&"|"&$K18 -> CM-004|0
A19: CM-004 | B19: Cash Flow from Operations (sign / periods) | C19: Credit Monitoring | D19: CFO negative for repeated periods | E19: 2 | F19: 1 negative period | G19: Count Exact | H19: 1 | I19: 1 | J19: exactly = value (1 negative period) | K19: 15 | L19: =$K19/INDEX('Indicator Master'!$N$4:$N$24,MATCH($A19,'Indicator Master'!$A$4:$A$24,0))*'Risk Bands (Config)'!$B$5 -> 37.5 | M19: =IF($K19=INDEX('Indicator Master'!$N$4:$N$24,MATCH($A19,'Indicator Master'!$A$4:$A$24,0)),1,0) -> 0 | O19: Elevated concern — one negative CFO period; isolated — watch for persistence. | P19: 1) Analyse the CFO driver (WC swing vs loss). 2) Obtain an explanation. 3) Monitor next period. | Q19: RM + Credit Analyst | R19: =$A19&"|"&$K19 -> CM-004|15
A20: CM-004 | B20: Cash Flow from Operations (sign / periods) | C20: Credit Monitoring | D20: CFO negative for repeated periods | E20: 3 | F20: 2 consecutive periods | G20: Count Exact | H20: 2 | I20: 2 | J20: exactly = value (2 consecutive) | K20: 30 | L20: =$K20/INDEX('Indicator Master'!$N$4:$N$24,MATCH($A20,'Indicator Master'!$A$4:$A$24,0))*'Risk Bands (Config)'!$B$5 -> 75 | M20: =IF($K20=INDEX('Indicator Master'!$N$4:$N$24,MATCH($A20,'Indicator Master'!$A$4:$A$24,0)),1,0) -> 0 | O20: High concern — two consecutive negative CFO periods; operations not generating cash. | P20: 1) Reassess debt-servicing capacity. 2) Seek promoter support; enhanced monitoring. 3) Flag to Credit. | Q20: Credit Committee / Zonal Credit | R20: =$A20&"|"&$K20 -> CM-004|30
A21: CM-004 | B21: Cash Flow from Operations (sign / periods) | C21: Credit Monitoring | D21: CFO negative for repeated periods | E21: 4 | F21: severe negative | G21: Count Threshold | H21: 3 | J21: ≥ lower (or severe negative) | K21: 40 | L21: =$K21/INDEX('Indicator Master'!$N$4:$N$24,MATCH($A21,'Indicator Master'!$A$4:$A$24,0))*'Risk Bands (Config)'!$B$5 -> 100 | M21: =IF($K21=INDEX('Indicator Master'!$N$4:$N$24,MATCH($A21,'Indicator Master'!$A$4:$A$24,0)),1,0) -> 1 | O21: Severe / critical — severe negative CFO; operations consuming significant cash — acute stress. | P21: 1) Reassess viability / restructuring need. 2) Corrective cash-flow plan. 3) Escalate to Credit. | Q21: Credit Head / Risk | R21: =$A21&"|"&$K21 -> CM-004|40
A22: CM-005 | B22: Current Ratio | C22: Credit Monitoring | D22: Current assets lower compared to current liabilities | E22: 1 | F22: >=1.33 | G22: Ratio Threshold | H22: 1.33 | J22: ≥ lower | K22: 0 | L22: =$K22/INDEX('Indicator Master'!$N$4:$N$24,MATCH($A22,'Indicator Master'!$A$4:$A$24,0))*'Risk Bands (Config)'!$B$5 -> 0 | M22: =IF($K22=INDEX('Indicator Master'!$N$4:$N$24,MATCH($A22,'Indicator Master'!$A$4:$A$24,0)),1,0) -> 0 | O22: Normal — current ratio ≥1.33; comfortable short-term liquidity. | P22: No remedial action required. Continue routine monitoring at the standard review cycle and record the reading. | Q22: RM (routine) | R22: =$A22&"|"&$K22 -> CM-005|0
A23: CM-005 | B23: Current Ratio | C23: Credit Monitoring | D23: Current assets lower compared to current liabilities | E23: 2 | F23: 1.10-1.32 | G23: Ratio Range | H23: 1.1 | I23: 1.33 | J23: ≥ lower & < upper | K23: 10 | L23: =$K23/INDEX('Indicator Master'!$N$4:$N$24,MATCH($A23,'Indicator Master'!$A$4:$A$24,0))*'Risk Bands (Config)'!$B$5 -> 28.571429 | M23: =IF($K23=INDEX('Indicator Master'!$N$4:$N$24,MATCH($A23,'Indicator Master'!$A$4:$A$24,0)),1,0) -> 0 | O23: Early warning — current ratio 1.10–1.32; adequate but easing liquidity. | P23: 1) Note the easing; review the WC position. 2) Watch the next statement. | Q23: Relationship Manager (Branch) | R23: =$A23&"|"&$K23 -> CM-005|10
A24: CM-005 | B24: Current Ratio | C24: Credit Monitoring | D24: Current assets lower compared to current liabilities | E24: 3 | F24: 1.00-1.09 | G24: Ratio Range | H24: 1 | I24: 1.1 | J24: ≥ lower & < upper | K24: 20 | L24: =$K24/INDEX('Indicator Master'!$N$4:$N$24,MATCH($A24,'Indicator Master'!$A$4:$A$24,0))*'Risk Bands (Config)'!$B$5 -> 57.142857 | M24: =IF($K24=INDEX('Indicator Master'!$N$4:$N$24,MATCH($A24,'Indicator Master'!$A$4:$A$24,0)),1,0) -> 0 | O24: Elevated concern — current ratio 1.00–1.09; thin liquidity buffer. | P24: 1) Assess NWC adequacy; seek promoter infusion. 2) Enhanced monitoring. 3) Flag to Credit. | Q24: RM + Credit Analyst | R24: =$A24&"|"&$K24 -> CM-005|20
A25: CM-005 | B25: Current Ratio | C25: Credit Monitoring | D25: Current assets lower compared to current liabilities | E25: 4 | F25: <1.00 | G25: Ratio Threshold | I25: 1 | J25: < upper | K25: 35 | L25: =$K25/INDEX('Indicator Master'!$N$4:$N$24,MATCH($A25,'Indicator Master'!$A$4:$A$24,0))*'Risk Bands (Config)'!$B$5 -> 100 | M25: =IF($K25=INDEX('Indicator Master'!$N$4:$N$24,MATCH($A25,'Indicator Master'!$A$4:$A$24,0)),1,0) -> 1 | O25: Severe / critical — current ratio below 1.00; current liabilities exceed current assets — liquidity stress. | P25: 1) Reassess limits and liquidity; corrective plan. 2) Monitor closely. 3) Escalate to Credit. | Q25: Credit Head / Risk | R25: =$A25&"|"&$K25 -> CM-005|35
A26: CM-006 | B26: Audit opinion classification | C26: Credit Monitoring | D26: Qualified audit opinion or going concern issue | E26: 1 | F26: No issue | G26: Ordinal Classification | J26: category | K26: 0 | L26: =$K26/INDEX('Indicator Master'!$N$4:$N$24,MATCH($A26,'Indicator Master'!$A$4:$A$24,0))*'Risk Bands (Config)'!$B$5 -> 0 | M26: =IF($K26=INDEX('Indicator Master'!$N$4:$N$24,MATCH($A26,'Indicator Master'!$A$4:$A$24,0)),1,0) -> 0 | O26: Normal — clean audit opinion; reliable reporting. | P26: No remedial action required. Continue routine monitoring at the standard review cycle and record the reading. | Q26: RM (routine) | R26: =$A26&"|"&$K26 -> CM-006|0
A27: CM-006 | B27: Audit opinion classification | C27: Credit Monitoring | D27: Qualified audit opinion or going concern issue | E27: 2 | F27: delayed/minor qualification | G27: Ordinal Classification | J27: category | K27: 10 | L27: =$K27/INDEX('Indicator Master'!$N$4:$N$24,MATCH($A27,'Indicator Master'!$A$4:$A$24,0))*'Risk Bands (Config)'!$B$5 -> 25 | M27: =IF($K27=INDEX('Indicator Master'!$N$4:$N$24,MATCH($A27,'Indicator Master'!$A$4:$A$24,0)),1,0) -> 0 | O27: Early warning — delayed audit or a minor qualification; low-level concern. | P27: 1) Read the qualification; assess materiality. 2) Seek clarification. 3) Monitor. | Q27: Relationship Manager (Branch) | R27: =$A27&"|"&$K27 -> CM-006|10
A28: CM-006 | B28: Audit opinion classification | C28: Credit Monitoring | D28: Qualified audit opinion or going concern issue | E28: 3 | F28: material qualification/change | G28: Ordinal Classification | J28: category | K28: 25 | L28: =$K28/INDEX('Indicator Master'!$N$4:$N$24,MATCH($A28,'Indicator Master'!$A$4:$A$24,0))*'Risk Bands (Config)'!$B$5 -> 62.5 | M28: =IF($K28=INDEX('Indicator Master'!$N$4:$N$24,MATCH($A28,'Indicator Master'!$A$4:$A$24,0)),1,0) -> 0 | O28: Elevated concern — material qualification or an auditor change; reporting reliability in question. | P28: 1) Adjust the analysis for the qualification. 2) Independent/special review. 3) Escalate to Credit. | Q28: Credit Committee / Zonal Credit | R28: =$A28&"|"&$K28 -> CM-006|25
A29: CM-006 | B29: Audit opinion classification | C29: Credit Monitoring | D29: Qualified audit opinion or going concern issue | E29: 4 | F29: going concern/adverse | G29: Ordinal Classification | J29: category | K29: 40 | L29: =$K29/INDEX('Indicator Master'!$N$4:$N$24,MATCH($A29,'Indicator Master'!$A$4:$A$24,0))*'Risk Bands (Config)'!$B$5 -> 100 | M29: =IF($K29=INDEX('Indicator Master'!$N$4:$N$24,MATCH($A29,'Indicator Master'!$A$4:$A$24,0)),1,0) -> 1 | O29: Severe / critical — going-concern or adverse opinion; doubt over viability. | P29: 1) Treat as a material adverse change; forensic review. 2) Reassess exposure and security. 3) Escalate to Credit Committee. | Q29: Credit Head / Risk | R29: =$A29&"|"&$K29 -> CM-006|40
A30: CM-007 | B30: NCLT/IBC admission status | C30: Credit Monitoring | D30: Insolvency filing against borrower or group | E30: 1 | F30: No case | G30: Ordinal Classification | J30: category | K30: 0 | L30: =$K30/INDEX('Indicator Master'!$N$4:$N$24,MATCH($A30,'Indicator Master'!$A$4:$A$24,0))*'Risk Bands (Config)'!$B$5 -> 0 | M30: =IF($K30=INDEX('Indicator Master'!$N$4:$N$24,MATCH($A30,'Indicator Master'!$A$4:$A$24,0)),1,0) -> 0 | O30: Normal — no insolvency/legal proceedings; clean status. | P30: No remedial action required. Continue routine monitoring at the standard review cycle and record the reading. | Q30: RM (routine) | R30: =$A30&"|"&$K30 -> CM-007|0
A31: CM-007 | B31: NCLT/IBC admission status | C31: Credit Monitoring | D31: Insolvency filing against borrower or group | E31: 2 | F31: civil/regulatory notice | G31: Ordinal Classification | J31: category | K31: 15 | L31: =$K31/INDEX('Indicator Master'!$N$4:$N$24,MATCH($A31,'Indicator Master'!$A$4:$A$24,0))*'Risk Bands (Config)'!$B$5 -> 30 | M31: =IF($K31=INDEX('Indicator Master'!$N$4:$N$24,MATCH($A31,'Indicator Master'!$A$4:$A$24,0)),1,0) -> 0 | O31: Early warning — a civil/regulatory notice; early legal exposure. | P31: 1) Obtain case details; assess materiality. 2) Legal review. 3) Monitor. | Q31: Relationship Manager (Branch) | R31: =$A31&"|"&$K31 -> CM-007|15
A32: CM-007 | B32: NCLT/IBC admission status | C32: Credit Monitoring | D32: Insolvency filing against borrower or group | E32: 3 | F32: multiple/material cases | G32: Ordinal Classification | J32: category | K32: 30 | L32: =$K32/INDEX('Indicator Master'!$N$4:$N$24,MATCH($A32,'Indicator Master'!$A$4:$A$24,0))*'Risk Bands (Config)'!$B$5 -> 60 | M32: =IF($K32=INDEX('Indicator Master'!$N$4:$N$24,MATCH($A32,'Indicator Master'!$A$4:$A$24,0)),1,0) -> 0 | O32: Elevated concern — multiple or material cases; escalating legal risk. | P32: 1) Quantify exposure; provision if material. 2) Protect the bank's charge. 3) Escalate to Credit/Legal. | Q32: RM + Credit Analyst | R32: =$A32&"|"&$K32 -> CM-007|30
A33: CM-007 | B33: NCLT/IBC admission status | C33: Credit Monitoring | D33: Insolvency filing against borrower or group | E33: 4 | F33: IBC/NCLT | G33: Ordinal Classification | J33: category | K33: 50 | L33: =$K33/INDEX('Indicator Master'!$N$4:$N$24,MATCH($A33,'Indicator Master'!$A$4:$A$24,0))*'Risk Bands (Config)'!$B$5 -> 100 | M33: =IF($K33=INDEX('Indicator Master'!$N$4:$N$24,MATCH($A33,'Indicator Master'!$A$4:$A$24,0)),1,0) -> 1 | O33: Severe / critical — IBC/NCLT admission; a default/recovery event. | P33: 1) Verify status; file/protect the claim. 2) Participate in the CoC; full provisioning. 3) Escalate to Credit Committee / Recovery. | Q33: Credit Head / Legal / Recovery | R33: =$A33&"|"&$K33 -> CM-007|50
A34: CM-008 | B34: Restructuring request status | C34: Credit Monitoring | D34: Moratorium, repayment extension, lower interest request | E34: 1 | F34: No request | G34: Ordinal Classification | J34: category | K34: 0 | L34: =$K34/INDEX('Indicator Master'!$N$4:$N$24,MATCH($A34,'Indicator Master'!$A$4:$A$24,0))*'Risk Bands (Config)'!$B$5 -> 0 | M34: =IF($K34=INDEX('Indicator Master'!$N$4:$N$24,MATCH($A34,'Indicator Master'!$A$4:$A$24,0)),1,0) -> 0 | O34: Normal — no restructuring sought; performing to terms. | P34: No remedial action required. Continue routine monitoring at the standard review cycle and record the reading. | Q34: RM (routine) | R34: =$A34&"|"&$K34 -> CM-008|0
A35: CM-008 | B35: Restructuring request status | C35: Credit Monitoring | D35: Moratorium, repayment extension, lower interest request | E35: 2 | F35: informal request | G35: Ordinal Classification | J35: category | K35: 15 | L35: =$K35/INDEX('Indicator Master'!$N$4:$N$24,MATCH($A35,'Indicator Master'!$A$4:$A$24,0))*'Risk Bands (Config)'!$B$5 -> 37.5 | M35: =IF($K35=INDEX('Indicator Master'!$N$4:$N$24,MATCH($A35,'Indicator Master'!$A$4:$A$24,0)),1,0) -> 0 | O35: Elevated concern — an informal restructuring/moratorium enquiry; early stress signal. | P35: 1) Obtain the rationale; assess genuine stress vs willful. 2) Seek cash-flow data. 3) Monitor. | Q35: RM + Credit Analyst | R35: =$A35&"|"&$K35 -> CM-008|15
A36: CM-008 | B36: Restructuring request status | C36: Credit Monitoring | D36: Moratorium, repayment extension, lower interest request | E36: 3 | F36: formal restructuring | G36: Ordinal Classification | J36: category | K36: 30 | L36: =$K36/INDEX('Indicator Master'!$N$4:$N$24,MATCH($A36,'Indicator Master'!$A$4:$A$24,0))*'Risk Bands (Config)'!$B$5 -> 75 | M36: =IF($K36=INDEX('Indicator Master'!$N$4:$N$24,MATCH($A36,'Indicator Master'!$A$4:$A$24,0)),1,0) -> 0 | O36: High concern — a formal restructuring request; acknowledged inability to service on current terms. | P36: 1) Conduct a viability/TEV assessment under the applicable framework. 2) Determine sacrifice/provisioning. 3) Escalate to Credit. | Q36: Credit Committee / Zonal Credit | R36: =$A36&"|"&$K36 -> CM-008|30
A37: CM-008 | B37: Restructuring request status | C37: Credit Monitoring | D37: Moratorium, repayment extension, lower interest request | E37: 4 | F37: repeated | G37: Ordinal Classification | J37: category | K37: 40 | L37: =$K37/INDEX('Indicator Master'!$N$4:$N$24,MATCH($A37,'Indicator Master'!$A$4:$A$24,0))*'Risk Bands (Config)'!$B$5 -> 100 | M37: =IF($K37=INDEX('Indicator Master'!$N$4:$N$24,MATCH($A37,'Indicator Master'!$A$4:$A$24,0)),1,0) -> 1 | O37: Severe / critical — repeated restructuring; chronic stress / evergreening risk. | P37: 1) Treat as chronic stress; guard against evergreening. 2) Reassess exit/recovery. 3) Escalate to Credit Committee. | Q37: Credit Head / Risk | R37: =$A37&"|"&$K37 -> CM-008|40
A38: CM-009 | B38: Security/collateral cover ratio | C38: Credit Monitoring | D38: Collateral value falling | E38: 1 | F38: ≥1.25 (adequate) | G38: Ratio Threshold | H38: 1.25 | J38: ≥ lower | K38: 0 | L38: =$K38/INDEX('Indicator Master'!$N$4:$N$24,MATCH($A38,'Indicator Master'!$A$4:$A$24,0))*'Risk Bands (Config)'!$B$5 -> 0 | M38: =IF($K38=INDEX('Indicator Master'!$N$4:$N$24,MATCH($A38,'Indicator Master'!$A$4:$A$24,0)),1,0) -> 0 | O38: Normal — collateral cover adequate and current. | P38: No remedial action required. Continue routine monitoring at the standard review cycle and record the reading. | Q38: RM (routine) | R38: =$A38&"|"&$K38 -> CM-009|0
A39: CM-009 | B39: Security/collateral cover ratio | C39: Credit Monitoring | D39: Collateral value falling | E39: 2 | F39: 1.10–1.25 (minor shortfall) | G39: Ratio Range | H39: 1.1 | I39: 1.25 | J39: ≥ lower & < upper | K39: 15 | L39: =$K39/INDEX('Indicator Master'!$N$4:$N$24,MATCH($A39,'Indicator Master'!$A$4:$A$24,0))*'Risk Bands (Config)'!$B$5 -> 37.5 | M39: =IF($K39=INDEX('Indicator Master'!$N$4:$N$24,MATCH($A39,'Indicator Master'!$A$4:$A$24,0)),1,0) -> 0 | O39: Elevated concern — a minor shortfall or lapse in cover; top-up needed. | P39: 1) Revalue security; seek a top-up. 2) Adjust DP to available cover. 3) Monitor to closure. | Q39: RM + Credit Analyst | R39: =$A39&"|"&$K39 -> CM-009|15
A40: CM-009 | B40: Security/collateral cover ratio | C40: Credit Monitoring | D40: Collateral value falling | E40: 3 | F40: 1.00–1.10 (major shortfall) | G40: Ratio Range | H40: 1 | I40: 1.1 | J40: ≥ lower & < upper | K40: 30 | L40: =$K40/INDEX('Indicator Master'!$N$4:$N$24,MATCH($A40,'Indicator Master'!$A$4:$A$24,0))*'Risk Bands (Config)'!$B$5 -> 75 | M40: =IF($K40=INDEX('Indicator Master'!$N$4:$N$24,MATCH($A40,'Indicator Master'!$A$4:$A$24,0)),1,0) -> 0 | O40: High concern — a major shortfall; the exposure is materially under-secured. | P40: 1) Obtain additional collateral/margin. 2) Reduce exposure to cover; reprice. 3) Escalate to Credit. | Q40: Credit Committee / Zonal Credit | R40: =$A40&"|"&$K40 -> CM-009|30
A41: CM-009 | B41: Security/collateral cover ratio | C41: Credit Monitoring | D41: Collateral value falling | E41: 4 | F41: <1.00 (under-secured) | G41: Ratio Threshold | I41: 1 | J41: < upper | K41: 40 | L41: =$K41/INDEX('Indicator Master'!$N$4:$N$24,MATCH($A41,'Indicator Master'!$A$4:$A$24,0))*'Risk Bands (Config)'!$B$5 -> 100 | M41: =IF($K41=INDEX('Indicator Master'!$N$4:$N$24,MATCH($A41,'Indicator Master'!$A$4:$A$24,0)),1,0) -> 1 | O41: Severe / critical — uninsured / significantly under-secured; the bank's security is impaired. | P41: 1) Demand additional security or accelerated repayment. 2) Perfect/protect the charge. 3) Escalate to Credit Committee. | Q41: Credit Head / Risk | R41: =$A41&"|"&$K41 -> CM-009|40
...

Sheet Overall Score Engine
A1: Overall Score Engine (Live Calculator)
A2: Yellow cells are inputs. Overall = average of normalised scores of applicable indicators with valid data (missing excluded, never zero). Credit Monitoring has no CRITICAL indicators, so no override applies.
A4: Borrower Name | B4: Acme Textiles Pvt Ltd
A5: Assessment Date | B5: 31-Aug-2026
A7: Total Indicators | B7: =COUNTA($A$23:$A$43) -> 21
A8: Applicable Indicators | B8: =COUNTIF($F$23:$F$43,"Y") -> 18 | C8: Indicators relevant to this borrower (N/A excluded).
A9: Scored (valid data) | B9: =SUM($J$23:$J$43) -> 17 | C9: Applicable AND data available AND a raw score entered.
A10: Missing Data (applicable) | B10: =COUNTIFS($F$23:$F$43,"Y",$G$23:$G$43,"N") -> 1 | C10: Applicable but no data — EXCLUDED from the average (not treated as zero).
A11: Not Applicable (N/A) | B11: =COUNTIF($F$23:$F$43,"N") -> 3
A12: Data Coverage % | B12: =IF(B8=0,0,B9/B8*100) -> 94.444444 | C12: Reported separately; does NOT affect the Overall Score.
A13: Sum of Normalised (scored) | B13: =SUM($K$23:$K$43) -> 473.09524
A14: Overall EWS Score | B14: =IF(B9=0,0,B13/B9) -> 27.829132 | C14: Average of normalised scores of applicable indicators with valid data.
A15: Numeric Risk Band | B15: =INDEX('Risk Bands (Config)'!$A$9:$A$13,MATCH(B14,'Risk Bands (Config)'!$D$9:$D$13,1)) -> Yellow | C15: Band implied by the Overall Score alone (before critical override).
A16: Critical Override Triggered? | B16: =IF(SUM($L$23:$L$43)>0,"YES","NO") -> NO | C16: YES if any CRITICAL indicator reaches the override trigger ('6. Risk Bands (Config)'!$B$6).
A17: Critical Indicators Fired | B17: None
A18: FINAL STATUS | B18: =IF(B16="YES","CRITICAL (Override)",IF(B12<'Risk Bands (Config)'!$B$16,"INSUFFICIENT DATA (band: "&B15&")",B15)) -> Yellow
A19: Final Interpretation | B19: =IF(B16="YES",INDEX('Risk Bands (Config)'!$E$9:$E$13,5),IF(B12<'Risk Bands (Config)'!$B$16,"Low data coverage — treat score as low-confidence; obtain missing data before acting.",INDEX('Risk Bands (Config)'!$E$9:$E$13,MATCH(B14,'Risk Bands (Config)'!$D$9:$D$13,1)))) -> Early Deterioration / Monitor
A20: Traceability: FINAL STATUS ← Overall Score / Critical Override ← per-indicator Normalised ← Raw Score ← borrower Observed Value ← applicable threshold band.
A22: UID | B22: Indicator | C22: Module | D22: Critical | E22: Max Score | F22: Applicable (Y/N) | G22: Data Available (Y/N) | H22: Observed Value / Note | I22: Raw Score | J22: Scored Flag | K22: Normalised Score | L22: Critical Fire | M22: Crit Fire UID (helper) | N22: What it signals & likely drivers | O22: Remedial action plan (step-by-step) | P22: Primary owner
A23: CM-001 | B23: DPD (days past due) | C23: Credit Monitoring | D23: =INDEX('Indicator Master'!$F$4:$F$24,MATCH($A23,'Indicator Master'!$A$4:$A$24,0)) -> No | E23: =INDEX('Indicator Master'!$N$4:$N$24,MATCH($A23,'Indicator Master'!$A$4:$A$24,0)) -> 40 | F23: Y | G23: Y | H23: One instalment ~12 days late, since regularised → band '1-30 DPD' | I23: 10 | J23: =IF(AND($F23="Y",$G23="Y",ISNUMBER($I23)),1,0) -> 1 | K23: =IF($J23=1,$I23/$E23*'Risk Bands (Config)'!$B$5,"") -> 25 | L23: =IF(AND($D23="Yes",$J23=1,$I23/$E23*'Risk Bands (Config)'!$B$5>='Risk Bands (Config)'!$B$6),1,0) -> 0 | M23: =IF($L23=1,$A23,"") | N23: =IF($J23=1,IFERROR(INDEX('Scoring Engine (Rules)'!$O$5:$O$89,MATCH($A23&"|"&$I23,'Scoring Engine (Rules)'!$R$5:$R$89,0)),""),"") -> Early warning — 1–30 days past due (SMA-0); a short cash-flow slip. | O23: =IF($J23=1,IFERROR(INDEX('Scoring Engine (Rules)'!$P$5:$P$89,MATCH($A23&"|"&$I23,'Scoring Engine (Rules)'!$R$5:$R$89,0)),""),"") -> 1) Contact the borrower; obtain the reason and a dated payment commitment. 2) Tag SMA-0. 3) Watch daily. | P23: =IF($J23=1,IFERROR(INDEX('Scoring Engine (Rules)'!$Q$5:$Q$89,MATCH($A23&"|"&$I23,'Scoring Engine (Rules)'!$R$5:$R$89,0)),""),"") -> Relationship Manager (Branch)
A24: CM-002 | B24: Excess over DP/limit % | C24: Credit Monitoring | D24: =INDEX('Indicator Master'!$F$4:$F$24,MATCH($A24,'Indicator Master'!$A$4:$A$24,0)) -> No | E24: =INDEX('Indicator Master'!$N$4:$N$24,MATCH($A24,'Indicator Master'!$A$4:$A$24,0)) -> 30 | F24: Y | G24: Y | H24: CC drawn ~4% over DP for a few days, since corrected → band 'Up to 5% breach' | I24: 10 | J24: =IF(AND($F24="Y",$G24="Y",ISNUMBER($I24)),1,0) -> 1 | K24: =IF($J24=1,$I24/$E24*'Risk Bands (Config)'!$B$5,"") -> 33.333333 | L24: =IF(AND($D24="Yes",$J24=1,$I24/$E24*'Risk Bands (Config)'!$B$5>='Risk Bands (Config)'!$B$6),1,0) -> 0 | M24: =IF($L24=1,$A24,"") | N24: =IF($J24=1,IFERROR(INDEX('Scoring Engine (Rules)'!$O$5:$O$89,MATCH($A24&"|"&$I24,'Scoring Engine (Rules)'!$R$5:$R$89,0)),""),"") -> Early warning — excess up to 5%; minor, likely a timing over-draw. | O24: =IF($J24=1,IFERROR(INDEX('Scoring Engine (Rules)'!$P$5:$P$89,MATCH($A24&"|"&$I24,'Scoring Engine (Rules)'!$R$5:$R$89,0)),""),"") -> 1) Regularise the excess promptly. 2) Ascertain the reason. 3) Allow no fresh excess. | P24: =IF($J24=1,IFERROR(INDEX('Scoring Engine (Rules)'!$Q$5:$Q$89,MATCH($A24&"|"&$I24,'Scoring Engine (Rules)'!$R$5:$R$89,0)),""),"") -> RM + Credit Analyst
A25: CM-003 | B25: GST turnover change % / vs bank credits | C25: Credit Monitoring | D25: =INDEX('Indicator Master'!$F$4:$F$24,MATCH($A25,'Indicator Master'!$A$4:$A$24,0)) -> No | E25: =INDEX('Indicator Master'!$N$4:$N$24,MATCH($A25,'Indicator Master'!$A$4:$A$24,0)) -> 35 | F25: Y | G25: Y | H25: GST turnover down ~30% vs prior period → band '20-40% decline' | I25: 20 | J25: =IF(AND($F25="Y",$G25="Y",ISNUMBER($I25)),1,0) -> 1 | K25: =IF($J25=1,$I25/$E25*'Risk Bands (Config)'!$B$5,"") -> 57.142857 | L25: =IF(AND($D25="Yes",$J25=1,$I25/$E25*'Risk Bands (Config)'!$B$5>='Risk Bands (Config)'!$B$6),1,0) -> 0 | M25: =IF($L25=1,$A25,"") | N25: =IF($J25=1,IFERROR(INDEX('Scoring Engine (Rules)'!$O$5:$O$89,MATCH($A25&"|"&$I25,'Scoring Engine (Rules)'!$R$5:$R$89,0)),""),"") -> Elevated concern — down 20–40%; material fall — demand loss or diversion of billing. | O25: =IF($J25=1,IFERROR(INDEX('Scoring Engine (Rules)'!$P$5:$P$89,MATCH($A25&"|"&$I25,'Scoring Engine (Rules)'!$R$5:$R$89,0)),""),"") -> 1) Reassess WC and projections. 2) Investigate under-reporting/diversion. 3) Enhanced monitoring; flag to Credit. | P25: =IF($J25=1,IFERROR(INDEX('Scoring Engine (Rules)'!$Q$5:$Q$89,MATCH($A25&"|"&$I25,'Scoring Engine (Rules)'!$R$5:$R$89,0)),""),"") -> RM + Credit Analyst
A26: CM-004 | B26: Cash Flow from Operations (sign / periods) | C26: Credit Monitoring | D26: =INDEX('Indicator Master'!$F$4:$F$24,MATCH($A26,'Indicator Master'!$A$4:$A$24,0)) -> No | E26: =INDEX('Indicator Master'!$N$4:$N$24,MATCH($A26,'Indicator Master'!$A$4:$A$24,0)) -> 40 | F26: Y | G26: Y | H26: One negative operating cash-flow quarter → band 'one negative period' | I26: 15 | J26: =IF(AND($F26="Y",$G26="Y",ISNUMBER($I26)),1,0) -> 1 | K26: =IF($J26=1,$I26/$E26*'Risk Bands (Config)'!$B$5,"") -> 37.5 | L26: =IF(AND($D26="Yes",$J26=1,$I26/$E26*'Risk Bands (Config)'!$B$5>='Risk Bands (Config)'!$B$6),1,0) -> 0 | M26: =IF($L26=1,$A26,"") | N26: =IF($J26=1,IFERROR(INDEX('Scoring Engine (Rules)'!$O$5:$O$89,MATCH($A26&"|"&$I26,'Scoring Engine (Rules)'!$R$5:$R$89,0)),""),"") -> Elevated concern — one negative CFO period; isolated — watch for persistence. | O26: =IF($J26=1,IFERROR(INDEX('Scoring Engine (Rules)'!$P$5:$P$89,MATCH($A26&"|"&$I26,'Scoring Engine (Rules)'!$R$5:$R$89,0)),""),"") -> 1) Analyse the CFO driver (WC swing vs loss). 2) Obtain an explanation. 3) Monitor next period. | P26: =IF($J26=1,IFERROR(INDEX('Scoring Engine (Rules)'!$Q$5:$Q$89,MATCH($A26&"|"&$I26,'Scoring Engine (Rules)'!$R$5:$R$89,0)),""),"") -> RM + Credit Analyst
A27: CM-005 | B27: Current Ratio | C27: Credit Monitoring | D27: =INDEX('Indicator Master'!$F$4:$F$24,MATCH($A27,'Indicator Master'!$A$4:$A$24,0)) -> No | E27: =INDEX('Indicator Master'!$N$4:$N$24,MATCH($A27,'Indicator Master'!$A$4:$A$24,0)) -> 35 | F27: Y | G27: Y | H27: Current ratio at 1.05 → band '1.00-1.09' | I27: 20 | J27: =IF(AND($F27="Y",$G27="Y",ISNUMBER($I27)),1,0) -> 1 | K27: =IF($J27=1,$I27/$E27*'Risk Bands (Config)'!$B$5,"") -> 57.142857 | L27: =IF(AND($D27="Yes",$J27=1,$I27/$E27*'Risk Bands (Config)'!$B$5>='Risk Bands (Config)'!$B$6),1,0) -> 0 | M27: =IF($L27=1,$A27,"") | N27: =IF($J27=1,IFERROR(INDEX('Scoring Engine (Rules)'!$O$5:$O$89,MATCH($A27&"|"&$I27,'Scoring Engine (Rules)'!$R$5:$R$89,0)),""),"") -> Elevated concern — current ratio 1.00–1.09; thin liquidity buffer. | O27: =IF($J27=1,IFERROR(INDEX('Scoring Engine (Rules)'!$P$5:$P$89,MATCH($A27&"|"&$I27,'Scoring Engine (Rules)'!$R$5:$R$89,0)),""),"") -> 1) Assess NWC adequacy; seek promoter infusion. 2) Enhanced monitoring. 3) Flag to Credit. | P27: =IF($J27=1,IFERROR(INDEX('Scoring Engine (Rules)'!$Q$5:$Q$89,MATCH($A27&"|"&$I27,'Scoring Engine (Rules)'!$R$5:$R$89,0)),""),"") -> RM + Credit Analyst
A28: CM-006 | B28: Audit opinion classification | C28: Credit Monitoring | D28: =INDEX('Indicator Master'!$F$4:$F$24,MATCH($A28,'Indicator Master'!$A$4:$A$24,0)) -> No | E28: =INDEX('Indicator Master'!$N$4:$N$24,MATCH($A28,'Indicator Master'!$A$4:$A$24,0)) -> 40 | F28: Y | G28: Y | H28: Clean audit opinion, no qualification → band 'No issue' | I28: 0 | J28: =IF(AND($F28="Y",$G28="Y",ISNUMBER($I28)),1,0) -> 1 | K28: =IF($J28=1,$I28/$E28*'Risk Bands (Config)'!$B$5,"") -> 0 | L28: =IF(AND($D28="Yes",$J28=1,$I28/$E28*'Risk Bands (Config)'!$B$5>='Risk Bands (Config)'!$B$6),1,0) -> 0 | M28: =IF($L28=1,$A28,"") | N28: =IF($J28=1,IFERROR(INDEX('Scoring Engine (Rules)'!$O$5:$O$89,MATCH($A28&"|"&$I28,'Scoring Engine (Rules)'!$R$5:$R$89,0)),""),"") -> Normal — clean audit opinion; reliable reporting. | O28: =IF($J28=1,IFERROR(INDEX('Scoring Engine (Rules)'!$P$5:$P$89,MATCH($A28&"|"&$I28,'Scoring Engine (Rules)'!$R$5:$R$89,0)),""),"") -> No remedial action required. Continue routine monitoring at the standard review cycle and record the reading. | P28: =IF($J28=1,IFERROR(INDEX('Scoring Engine (Rules)'!$Q$5:$Q$89,MATCH($A28&"|"&$I28,'Scoring Engine (Rules)'!$R$5:$R$89,0)),""),"") -> RM (routine)
A29: CM-007 | B29: NCLT/IBC admission status | C29: Credit Monitoring | D29: =INDEX('Indicator Master'!$F$4:$F$24,MATCH($A29,'Indicator Master'!$A$4:$A$24,0)) -> No | E29: =INDEX('Indicator Master'!$N$4:$N$24,MATCH($A29,'Indicator Master'!$A$4:$A$24,0)) -> 50 | F29: Y | G29: Y | H29: No insolvency or legal proceedings on record → band 'No case' | I29: 0 | J29: =IF(AND($F29="Y",$G29="Y",ISNUMBER($I29)),1,0) -> 1 | K29: =IF($J29=1,$I29/$E29*'Risk Bands (Config)'!$B$5,"") -> 0 | L29: =IF(AND($D29="Yes",$J29=1,$I29/$E29*'Risk Bands (Config)'!$B$5>='Risk Bands (Config)'!$B$6),1,0) -> 0 | M29: =IF($L29=1,$A29,"") | N29: =IF($J29=1,IFERROR(INDEX('Scoring Engine (Rules)'!$O$5:$O$89,MATCH($A29&"|"&$I29,'Scoring Engine (Rules)'!$R$5:$R$89,0)),""),"") -> Normal — no insolvency/legal proceedings; clean status. | O29: =IF($J29=1,IFERROR(INDEX('Scoring Engine (Rules)'!$P$5:$P$89,MATCH($A29&"|"&$I29,'Scoring Engine (Rules)'!$R$5:$R$89,0)),""),"") -> No remedial action required. Continue routine monitoring at the standard review cycle and record the reading. | P29: =IF($J29=1,IFERROR(INDEX('Scoring Engine (Rules)'!$Q$5:$Q$89,MATCH($A29&"|"&$I29,'Scoring Engine (Rules)'!$R$5:$R$89,0)),""),"") -> RM (routine)
A30: CM-008 | B30: Restructuring request status | C30: Credit Monitoring | D30: =INDEX('Indicator Master'!$F$4:$F$24,MATCH($A30,'Indicator Master'!$A$4:$A$24,0)) -> No | E30: =INDEX('Indicator Master'!$N$4:$N$24,MATCH($A30,'Indicator Master'!$A$4:$A$24,0)) -> 40 | F30: Y | G30: Y | H30: Informal moratorium request raised by the borrower → band 'informal request' | I30: 15 | J30: =IF(AND($F30="Y",$G30="Y",ISNUMBER($I30)),1,0) -> 1 | K30: =IF($J30=1,$I30/$E30*'Risk Bands (Config)'!$B$5,"") -> 37.5 | L30: =IF(AND($D30="Yes",$J30=1,$I30/$E30*'Risk Bands (Config)'!$B$5>='Risk Bands (Config)'!$B$6),1,0) -> 0 | M30: =IF($L30=1,$A30,"") | N30: =IF($J30=1,IFERROR(INDEX('Scoring Engine (Rules)'!$O$5:$O$89,MATCH($A30&"|"&$I30,'Scoring Engine (Rules)'!$R$5:$R$89,0)),""),"") -> Elevated concern — an informal restructuring/moratorium enquiry; early stress signal. | O30: =IF($J30=1,IFERROR(INDEX('Scoring Engine (Rules)'!$P$5:$P$89,MATCH($A30&"|"&$I30,'Scoring Engine (Rules)'!$R$5:$R$89,0)),""),"") -> 1) Obtain the rationale; assess genuine stress vs willful. 2) Seek cash-flow data. 3) Monitor. | P30: =IF($J30=1,IFERROR(INDEX('Scoring Engine (Rules)'!$Q$5:$Q$89,MATCH($A30&"|"&$I30,'Scoring Engine (Rules)'!$R$5:$R$89,0)),""),"") -> RM + Credit Analyst
A31: CM-009 | B31: Security/collateral cover ratio | C31: Credit Monitoring | D31: =INDEX('Indicator Master'!$F$4:$F$24,MATCH($A31,'Indicator Master'!$A$4:$A$24,0)) -> No | E31: =INDEX('Indicator Master'!$N$4:$N$24,MATCH($A31,'Indicator Master'!$A$4:$A$24,0)) -> 40 | F31: Y | G31: Y | H31: Minor collateral-cover shortfall pending revaluation → band 'minor shortfall/lapse' | I31: 15 | J31: =IF(AND($F31="Y",$G31="Y",ISNUMBER($I31)),1,0) -> 1 | K31: =IF($J31=1,$I31/$E31*'Risk Bands (Config)'!$B$5,"") -> 37.5 | L31: =IF(AND($D31="Yes",$J31=1,$I31/$E31*'Risk Bands (Config)'!$B$5>='Risk Bands (Config)'!$B$6),1,0) -> 0 | M31: =IF($L31=1,$A31,"") | N31: =IF($J31=1,IFERROR(INDEX('Scoring Engine (Rules)'!$O$5:$O$89,MATCH($A31&"|"&$I31,'Scoring Engine (Rules)'!$R$5:$R$89,0)),""),"") -> Elevated concern — a minor shortfall or lapse in cover; top-up needed. | O31: =IF($J31=1,IFERROR(INDEX('Scoring Engine (Rules)'!$P$5:$P$89,MATCH($A31&"|"&$I31,'Scoring Engine (Rules)'!$R$5:$R$89,0)),""),"") -> 1) Revalue security; seek a top-up. 2) Adjust DP to available cover. 3) Monitor to closure. | P31: =IF($J31=1,IFERROR(INDEX('Scoring Engine (Rules)'!$Q$5:$Q$89,MATCH($A31&"|"&$I31,'Scoring Engine (Rules)'!$R$5:$R$89,0)),""),"") -> RM + Credit Analyst
A32: CM-010 | B32: Insurance validity / days to expiry | C32: Credit Monitoring | D32: =INDEX('Indicator Master'!$F$4:$F$24,MATCH($A32,'Indicator Master'!$A$4:$A$24,0)) -> No | E32: =INDEX('Indicator Master'!$N$4:$N$24,MATCH($A32,'Indicator Master'!$A$4:$A$24,0)) -> 40 | F32: Y | G32: Y | H32: Stock insurance lapsed; renewal pending → band 'minor shortfall/lapse' | I32: 15 | J32: =IF(AND($F32="Y",$G32="Y",ISNUMBER($I32)),1,0) -> 1 | K32: =IF($J32=1,$I32/$E32*'Risk Bands (Config)'!$B$5,"") -> 37.5 | L32: =IF(AND($D32="Yes",$J32=1,$I32/$E32*'Risk Bands (Config)'!$B$5>='Risk Bands (Config)'!$B$6),1,0) -> 0 | M32: =IF($L32=1,$A32,"") | N32: =IF($J32=1,IFERROR(INDEX('Scoring Engine (Rules)'!$O$5:$O$89,MATCH($A32&"|"&$I32,'Scoring Engine (Rules)'!$R$5:$R$89,0)),""),"") -> Elevated concern — a minor lapse or approaching expiry; renewal needed. | O32: =IF($J32=1,IFERROR(INDEX('Scoring Engine (Rules)'!$P$5:$P$89,MATCH($A32&"|"&$I32,'Scoring Engine (Rules)'!$R$5:$R$89,0)),""),"") -> 1) Follow up for renewal with the bank clause; note the expiry. 2) Obtain the policy. 3) Monitor. | P32: =IF($J32=1,IFERROR(INDEX('Scoring Engine (Rules)'!$Q$5:$Q$89,MATCH($A32&"|"&$I32,'Scoring Engine (Rules)'!$R$5:$R$89,0)),""),"") -> RM + Credit Analyst
A33: CM-011 | B33: Top-customer revenue concentration % | C33: Credit Monitoring | D33: =INDEX('Indicator Master'!$F$4:$F$24,MATCH($A33,'Indicator Master'!$A$4:$A$24,0)) -> No | E33: =INDEX('Indicator Master'!$N$4:$N$24,MATCH($A33,'Indicator Master'!$A$4:$A$24,0)) -> 30 | F33: Y | G33: Y | H33: Top customer ~32% of revenue → band '25-40%' | I33: 10 | J33: =IF(AND($F33="Y",$G33="Y",ISNUMBER($I33)),1,0) -> 1 | K33: =IF($J33=1,$I33/$E33*'Risk Bands (Config)'!$B$5,"") -> 33.333333 | L33: =IF(AND($D33="Yes",$J33=1,$I33/$E33*'Risk Bands (Config)'!$B$5>='Risk Bands (Config)'!$B$6),1,0) -> 0 | M33: =IF($L33=1,$A33,"") | N33: =IF($J33=1,IFERROR(INDEX('Scoring Engine (Rules)'!$O$5:$O$89,MATCH($A33&"|"&$I33,'Scoring Engine (Rules)'!$R$5:$R$89,0)),""),"") -> Early warning — concentration 25–40%; moderate dependence on a key customer. | O33: =IF($J33=1,IFERROR(INDEX('Scoring Engine (Rules)'!$P$5:$P$89,MATCH($A33&"|"&$I33,'Scoring Engine (Rules)'!$R$5:$R$89,0)),""),"") -> 1) Review the customer mix. 2) Encourage diversification. 3) Monitor the key customer's health. | P33: =IF($J33=1,IFERROR(INDEX('Scoring Engine (Rules)'!$Q$5:$Q$89,MATCH($A33&"|"&$I33,'Scoring Engine (Rules)'!$R$5:$R$89,0)),""),"") -> RM + Credit Analyst
A34: CM-012 | B34: Top-supplier purchase concentration % | C34: Credit Monitoring | D34: =INDEX('Indicator Master'!$F$4:$F$24,MATCH($A34,'Indicator Master'!$A$4:$A$24,0)) -> No | E34: =INDEX('Indicator Master'!$N$4:$N$24,MATCH($A34,'Indicator Master'!$A$4:$A$24,0)) -> 30 | F34: Y | G34: Y | H34: Top supplier ~18% of purchases → band '<25% exposure' | I34: 0 | J34: =IF(AND($F34="Y",$G34="Y",ISNUMBER($I34)),1,0) -> 1 | K34: =IF($J34=1,$I34/$E34*'Risk Bands (Config)'!$B$5,"") -> 0 | L34: =IF(AND($D34="Yes",$J34=1,$I34/$E34*'Risk Bands (Config)'!$B$5>='Risk Bands (Config)'!$B$6),1,0) -> 0 | M34: =IF($L34=1,$A34,"") | N34: =IF($J34=1,IFERROR(INDEX('Scoring Engine (Rules)'!$O$5:$O$89,MATCH($A34&"|"&$I34,'Scoring Engine (Rules)'!$R$5:$R$89,0)),""),"") -> Normal — top-supplier concentration below 25%; diversified sourcing. | O34: =IF($J34=1,IFERROR(INDEX('Scoring Engine (Rules)'!$P$5:$P$89,MATCH($A34&"|"&$I34,'Scoring Engine (Rules)'!$R$5:$R$89,0)),""),"") -> No remedial action required. Continue routine monitoring at the standard review cycle and record the reading. | P34: =IF($J34=1,IFERROR(INDEX('Scoring Engine (Rules)'!$Q$5:$Q$89,MATCH($A34&"|"&$I34,'Scoring Engine (Rules)'!$R$5:$R$89,0)),""),"") -> RM (routine)
... A36: CM-014 | B36: Commodity exposure/stress classification | C36: Credit Monitoring | D36: =INDEX('Indicator Master'!$F$4:$F$24,MATCH($A36,'Indicator Master'!$A$4:$A$24,0)) -> No | E36: =INDEX('Indicator Master'!$N$4:$N$24,MATCH($A36,'Indicator Master'!$A$4:$A$24,0)) -> 35 | F36: Y | G36: Y | H36: Cotton-price volatility; moderate margin pressure → band 'moderate exposure/stress' | I36: 10 | J36: =IF(AND($F36="Y",$G36="Y",ISNUMBER($I36)),1,0) -> 1 | K36: =IF($J36=1,$I36/$E36*'Risk Bands (Config)'!$B$5,"") -> 28.571429 | L36: =IF(AND($D36="Yes",$J36=1,$I36/$E36*'Risk Bands (Config)'!$B$5>='Risk Bands (Config)'!$B$6),1,0) -> 0 | M36: =IF($L36=1,$A36,"") | N36: =IF($J36=1,IFERROR(INDEX('Scoring Engine (Rules)'!$O$5:$O$89,MATCH($A36&"|"&$I36,'Scoring Engine (Rules)'!$R$5:$R$89,0)),""),"") -> Early warning — moderate commodity exposure; margin sensitivity. | O36: =IF($J36=1,IFERROR(INDEX('Scoring Engine (Rules)'!$P$5:$P$89,MATCH($A36&"|"&$I36,'Scoring Engine (Rules)'!$R$5:$R$89,0)),""),"") -> 1) Assess the pass-through ability. 2) Encourage hedging. 3) Monitor margins. | P36: =IF($J36=1,IFERROR(INDEX('Scoring Engine (Rules)'!$Q$5:$Q$89,MATCH($A36&"|"&$I36,'Scoring Engine (Rules)'!$R$5:$R$89,0)),""),"") -> Relationship Manager (Branch)
