Workbook

Sheet README
A1: EWS Functional Logic & Scoring Workbook (v1.13)
A2: 43 indicators (EWS-001…EWS-043). “Security Cover” removed; DSCR, Leverage Ratio, Current Ratio and Carbon Emission thresholds revised per the Indicator Master. Critical Combination rule retained.
A4: What changed in v1.13
A5: • Removed the indicator “Security Cover” (was EWS-044) from every sheet.
A6: • Revised thresholds/scores per the Indicator Master for DSCR (EWS-041: 1.25–1.50 = 0, <1.25 = 40), Leverage Ratio (EWS-042: ≤2.0 = 0, 2.0–3.0 = 10, >3.0 = 40), Current Ratio (EWS-043: ≥1.33 = 0, 1–1.33 = 10, <1.00 = 40) and Carbon Emission (EWS-038: within norms = 0, breach = 15, penalty/action = 40).
A7: • Sequence remains continuous EWS-001…EWS-043 (43 indicators) — the removed indicator was last, so no renumbering of others was needed.
A8: • All downstream sheets (Functional Logic, Scoring Engine (Rules), Overall Score Engine, Borrower Example, Recommendations) rebuilt from the Indicator Master.
A9: • The Critical Combination rule is unchanged (pairs EWS-004/011, EWS-005/014, EWS-009/012).
A11: Scoring & combination logic
A12: • Normalised = Raw ÷ Max Score × 100. Overall = average of normalised of applicable indicators with valid data (missing excluded, N/A excluded).
A13: • Critical Override fires on (a) any Critical indicator at its trigger, OR (b) any Critical Combination pair co-occurring (both members breached above Normal — trigger configurable on the Config sheet).
A14: • Pair 1 — EWS-004 (Payment Default Frequency) + EWS-011 (Creditor days). Pair 2 — EWS-005 (Repayment source) + EWS-014 (Unsecured loans change %). Pair 3 — EWS-009 (Debtor days) + EWS-012 (Provisions/write-offs).
... A17: • Indicator Master · Functional Logic · Scoring Engine (Rules) · Overall Score Engine (with the Critical Combination block) · Borrower Example · Risk Bands (Config) · Alert Lifecycle · Recommendations.

Sheet Indicator Master
A1: EWS Indicator Master
A3: UID | B3: Module | C3: Indicator | D3: Description | E3: Category | F3: Critical (Yes/No) | G3: What to Track (Input) | H3: Data Source Channel | I3: Acquisition Mechanism | J3: Data Type | K3: Update Frequency | L3: Functional Calculation Formula | M3: Threshold & Score | N3: Max Score
A4: EWS-001 | B4: EWS | C4: Utilization % (outstanding / sanctioned) | D4: High utilization of working capital limits | E4: Account Conduct | F4: No | G4: CC/OD utilization above 85-90% continuously | H4: Bank Core System (CBS) | I4: Direct CBS extract | J4: Quantitative | K4: Daily | L4: Utilization% = Utilized / Sanctioned; flag if >85% sustained | M4: <85% = 0 | 85-90% = 10 | 90-95% = 20 | >95% for 30+ days = 30 | N4: 30
A5: EWS-002 | B5: EWS | C5: Count of ad-hoc limit requests (rolling 12m) | D5: Frequent ad-hoc limit requests | E5: Account Conduct | F5: No | G5: Temporary limit enhancement requests | H5: Bank Core System (CBS) | I5: Map in data discovery | J5: Quantitative | K5: Event | L5: Compute Count of ad-hoc limit requests (rolling 12m) then compare to threshold bands | M5: 0-1 request/year = 0 | 2 = 10 | 3+ = 20 | emergency request = 30 | N5: 30
A6: EWS-003 | B6: EWS | C6: Monthly sales vs credit summation | D6: Lower bank account credits (Not applicable to Consortium Account) | E6: Account Conduct | F6: Yes | G6: Reduction in monthly credits in operating account | H6: Bank Core System (CBS) | I6: Direct CBS extract | J6: Quantitative | K6: Monthly | L6: CreditChange% = (CurrentMonthCredits - Baseline)/Baseline | M6: Stable/Variation upto 5% = 0 | 5-10% decline = 10 | 10-15% decline = 20 | >15% = 35 | N6: 35
A7: EWS-004 | B7: EWS | C7: Payment Default Frequency | D7: Frequent Cheque Bounces | E7: Account Conduct | F7: No | G7: Cheque returns, Cheque Bounce, ECS bounce, frequent TODs | H7: Bank Core System (CBS) | I7: Direct CBS extract | J7: Quantitative | K7: Daily | L7: Compute Count of conduct events (rolling 90d) then compare to threshold bands | M7: 0 = 0 | 1 = 5 | 2 = 15 | 3+ in 90 days = 25 | N7: 25
A8: EWS-005 | B8: EWS | C8: Repayment source classification | D8: Repayment out of other source of funds instead of sales | E8: Account Conduct | F8: No | G8: Repayment from unrelated parties or group accounts | H8: Bank Core System (CBS) | I8: Direct CBS extract | J8: Qualitative | K8: Event | L8: Classify event severity for 'Change in repayment source' (no numeric calc) | M8: Own operating cash flow = 0 | group support = 15 | unrelated source = 30 | repeated third-party payments = 40 | N8: 40
A9: EWS-006 | B9: EWS | C9: Stock reported vs audited variance % | D9: Mismatch in stock statement and financials | E9: Audit | F9: No | G9: Difference between reported stock and audited numbers | H9: Bank-provided Financial Statements | I9: Audited financials / CMA | J9: Quantitative | K9: Quarterly | L9: Compute Stock reported vs audited variance % then compare to threshold bands | M9: 0% variance = 0 | upto 10% = 10 | upto 20% = 20 | >20% = 30 | N9: 30
A10: EWS-007 | B10: EWS | C10: Sales turnover YoY/QoQ change % | D10: Decline in sales turnover | E10: Financial Performance | F10: Yes | G10: Monthly/quarterly sales drop | H10: Bank-provided Financial Statements | I10: Audited financials / CMA | J10: Quantitative | K10: Quarterly | L10: SalesChange% vs prior comparable period | M10: Stable/Variation upto 5% = 0 | 5-10% decline = 10 | 10-15% decline = 20 | >15% = 35 | N10: 35
A11: EWS-008 | B11: EWS | C11: EBITDA margin change % | D11: Decline in operating profit margin | E11: Financial Performance | F11: No | G11: EBITDA margin falling over periods | H11: Bank-provided Financial Statements | I11: Map in data discovery | J11: Quantitative | K11: Quarterly | L11: Compute EBITDA margin change % then compare to threshold bands | M11: Stable/Variation upto 5% = 0 | 5-10% decline = 10 | 10-15% decline = 20 | >15% = 35 | N11: 35
A12: EWS-009 | B12: EWS | C12: Debtor days vs normal | D12: Rising debtor days | E12: Financial Performance | F12: No | G12: Receivable days increasing sharply | H12: Bank-provided Financial Statements | I12: Audited financials / CMA | J12: Quantitative | K12: Quarterly | L12: DebtorDaysDelta = DebtorDays - Normal | M12: Within normal = 0 | upto 10 days = 10 | 10-20 days = 20 | >20 days = 30 | N12: 30
A13: EWS-010 | B13: EWS | C13: Inventory days vs normal | D13: Rising inventory days | E13: Financial Performance | F13: No | G13: Inventory holding period increasing | H13: Bank-provided Financial Statements | I13: Audited financials / CMA | J13: Quantitative | K13: Quarterly | L13: Compute Inventory days vs normal (delta days) then compare to threshold bands | M13: Within normal = 0 | +15-30 days = 10 | +30-60 days = 20 | +60 days = 30 | N13: 30
A14: EWS-011 | B14: EWS | C14: Creditor days vs normal | D14: Rising creditor days | E14: Financial Performance | F14: No | G14: Payables increasing beyond normal cycle | H14: Bank-provided Financial Statements | I14: Audited financials / CMA | J14: Quantitative | K14: Quarterly | L14: Compute Creditor days vs normal (delta days) then compare to threshold bands | M14: Within normal = 0 | +15-30 days = 10 | +30-60 days = 20 | +60 days = 30 | N14: 30 | O14: Link with 4th indicator - combination
A15: EWS-012 | B15: EWS | C15: Provisions/write-offs change % | D15: Large write-offs or provisions | E15: Financial Performance | F15: No | G15: Increase in bad debts / provisions | H15: Bank-provided Financial Statements | I15: Audited financials / CMA | J15: Quantitative | K15: Annual | L15: Compute Provisions/write-offs change % then compare to threshold bands | M15: ≤ 10% increase = 0 | >10% to 25% increase = 15 | >25% to 50% increase = 30 | >50% increase = 40 | N15: 40 | O15: Link with 9th
A16: EWS-013 | B16: EWS | C16: Actual vs CMA projection variance % | D16: Projected vs actual performance mismatch | E16: Financial Performance | F16: No | G16: Actual sales/profit/cash flow lower than CMA projections | H16: Bank Core System (CBS) + Financials Statement | I16: Map in data discovery | J16: Quantitative | K16: Quarterly | L16: Compute Actual vs CMA projection variance % then compare to threshold bands | M16: <5% = 0 | 5-10% = 10 | 10-15% = 20 | >15% = 35 | N16: 35
A17: EWS-014 | B17: EWS | C17: Unsecured loans change % | D17: Large unsecured loans taken | E17: Financial Performance | F17: Yes | G17: Increase in loans from promoters/group/private lenders | H17: Bank Core System (CBS) + Financials Statement | I17: Map in data discovery | J17: Quantitative | K17: Annual | L17: Compute Unsecured loans change % then compare to threshold bands | M17: ≤ 10% increase = 0 | >10% to 25% increase = 10 | >25% to 50% increase = 25 | >50% increase = 35 | N17: 35 | O17: Link with 5th
A18: EWS-015 | B18: EWS | C18: Finance cost growth vs sales growth % | D18: High finance cost growth | E18: Financial Performance | F18: No | G18: Interest cost rising faster than sales/profit | H18: Bank-provided Financial Statements | I18: Audited financials / CMA | J18: Quantitative | K18: Annual | L18: Compute Finance cost growth vs sales growth % then compare to threshold bands | M18: Stable = 0 | deterioration 10-20% = 10 | 20-40% = 20 | >40% or negative net worth = 40 | N18: 40
A19: EWS-016 | B19: EWS | C19: LC devolvement events | D19: LC devolvement | E19: Facility Conduct | F19: No | G19: Letter of credit not honoured by borrower | H19: Bank System (Trade Fin.) | I19: Trade-finance / Non-Fund Based (NFB) module | J19: Qualitative | K19: Event | L19: Classify event severity for 'LC devolvement' (no numeric calc) | M19: No event = 0 | one event = 15 | repeated events = 50 | N19: 50
A20: EWS-017 | B20: EWS | C20: BG invocation events | D20: Bank guarantee invocation | E20: Facility Conduct | F20: No | G20: BG invoked by beneficiary | H20: Bank System (Trade Fin.) | I20: Trade-finance / Non-Fund Based (NFB) module | J20: Qualitative | K20: Event | L20: Classify event severity for 'Bank guarantee invocation' (no numeric calc) | M20: No event = 0 | one event = 15 | repeated events = 50 | N20: 50
A21: EWS-018 | B21: EWS | C21: Rating notch movement | D21: Internal Rating downgrade | E21: Rating | F21: No | G21: Internal credit rating downgrade | H21: External (Subscription) | I21: Rating-agency feed / internal rating | J21: Qualitative | K21: Event | L21: Classify event severity for 'Rating downgrade' (no numeric calc) | M21: No change = 0 | one-notch downgrade = 15 | multi-notch/watchlist = 25 | below investment grade = 40 | N21: 40
A22: EWS-019 | B22: EWS | C22: Frequent change in Financial year/Accounting period | D22: Frequent change in Financial year/Accounting period of borrower | E22: Financial Reporting | F22: No | G22: Change in Financial year, unusual extension or shortening of financial year | H22: External + Internal Docs | I22: Audited financials and Ministry of Corporate Affairs (MCA) filings | J22: Qualitative | K22: Annual | L22: Count auditor/audit-year changes over a defined historical period and assess associated audit observations/qualifications | M22: No change/irregularity = 0 | Change in FY = 10 | Frequent/repeated change in FY = 25 | Change in FY accompanied by going-concern/adverse opinion or significant reporting concern = 40 | N22: 40
A23: EWS-020 | B23: EWS | C23: Auditor change events | D23: Frequent change of auditor | E23: Audit | F23: No | G23: Auditor resignation or repeated change | H23: External + Internal Docs | I23: Audited financials and Ministry of Corporate Affairs (MCA) filings | J23: Qualitative | K23: Event | L23: Classify event severity for 'Frequent change of auditors' (no numeric calc) | M23: No issue = 0 | delayed/minor qualification = 10 | material qualification/change = 25 | going concern/adverse = 40 | N23: 40
A24: EWS-021 | B24: EWS | C24: Key management change events | D24: Key personnel resignation or management exit | E24: Management Risk | F24: No | G24: Key promoter/director/CFO exit | H24: Bank-provided Financial Statements | I24: Map in data discovery | J24: Qualitative | K24: Event | L24: Classify event severity for 'Promoter resignation or management exit' (no numeric calc) | M24: No adverse change = 0 | moderate change = 10 | sudden key exit = 25 | control issue = 40 | N24: 40
A25: EWS-022 | B25: EWS | C25: % promoter shares pledged | D25: Promoter share pledge increase | E25: Management Risk | F25: No | G25: Higher pledged promoter shares | H25: External (Market/Filings) | I25: Exchange/Ministry of Corporate Affairs (MCA) filings | J25: Quantitative | K25: Event | L25: Compute % promoter shares pledged (delta) then compare to threshold bands | M25: ≤0% = 0 | >0% to ≤5% = 10 | >5% to ≤10% = 20 | >10% to ≤20% = 30 | >20% = 40 | N25: 40
A26: EWS-023 | B26: EWS | C26: Decline in promoter holding % | D26: Decline in promoter holding | E26: Management Risk | F26: No | G26: Significant reduction in promoter stake | H26: External (Market/Filings) | I26: Exchange/Ministry of Corporate Affairs (MCA) filings | J26: Quantitative | K26: Event | L26: Compute Promoter holding % (delta) then compare to threshold bands | M26: ≤0% decline = 0 | >0% to ≤5% decline = 10 | >5% to ≤10% decline = 20 | >10% to ≤20% decline = 30 | >20% decline = 40 | N26: 40
A27: EWS-024 | B27: EWS | C27: RPT value/share change % | D27: Related party transactions increase | E27: Management Risk | F27: No | G27: Large group-company transactions | H27: External + Internal Docs | I27: Audited financials and Ministry of Corporate Affairs (MCA) filings | J27: Quantitative | K27: Annual | L27: Compute RPT value/share change % then compare to threshold bands | M27: ≤0% = 0 | >0% to ≤10% = 10 | >10% to ≤25% = 25 | >25% = 40 | N27: 40
A28: EWS-025 | B28: EWS | C28: Group-entity stress classification | D28: Group entity stress | E28: Group Risk | F28: No | G28: Default, downgrade, insolvency, or stress in related/group company | H28: External + Internal Docs | I28: Map in data discovery | J28: Qualitative | K28: Event | L28: Classify event severity for 'Group entity stress' (no numeric calc) | M28: No group stress = 0 | downgrade/legal event = 20 | default/IBC in group = 40 | N28: 40
A29: EWS-026 | B29: EWS | C29: Statutory overdues | D29: Tax or statutory dues delay | E29: Compliance | F29: Yes | G29: Delay in GST, PF, TDS, income tax payment | H29: Bank Core System (CBS) + Financials Statement | I29: Map in data discovery | J29: Quantitative | K29: Monthly | L29: Compute Months of statutory dues overdue then compare to threshold bands | M29: On time = 0 | 1 month delayed = 10 | 2 months delayed = 20 | 3+ months = 35 | N29: 35
... A46: EWS-043 | B46: EWS | C46: Current Ratio | D46: Current Ratio (Current Assets / Current Liabilities) | E46: Financial Performance | F46: No | G46: Current ratio | H46: Audited financials / spreading | I46: Financial spreading | J46: Quantitative | K46: Quarterly / Annual | L46: Current Assets / Current Liabilities | M46: ≥1.33 = 0 | 1–1.33 = 10 | <1.00 = 40 | N46: 40

Sheet Functional Logic
A1: Functional Logic (per indicator)
A2: Input → Calculation/Classification → Threshold Evaluation → Raw Score → Normalised Score. Max Score links to the Master.
A4: UID | B4: Indicator | C4: Module | D4: Step 1 — Input (What to Track) | E4: Step 2 — Calculation / Classification | F4: Step 3 — Threshold Evaluation (bands) | G4: Max Score | H4: Step 4 — Raw Score rule | I4: Step 5 — Normalised Score
A5: EWS-001 | B5: Utilization % (outstanding / sanctioned) | C5: EWS | D5: CC/OD utilization above 85-90% continuously | E5: Utilization% = Utilized / Sanctioned; flag if >85% sustained | F5: <85% = 0 | 85-90% = 10 | 90-95% = 20 | >95% for 30+ days = 30 | G5: =INDEX('Indicator Master'!$N$4:$N$46,MATCH($A5,'Indicator Master'!$A$4:$A$46,0)) -> 30 | H5: Raw Score = score of the single band whose condition the borrower value satisfies; 0 if none is breached. | I5: Normalised = Raw ÷ Max Score × 100 (0–100). Fed into the Overall Score Engine.
A6: EWS-002 | B6: Count of ad-hoc limit requests (rolling 12m) | C6: EWS | D6: Temporary limit enhancement requests | E6: Compute Count of ad-hoc limit requests (rolling 12m) then compare to threshold bands | F6: 0-1 request/year = 0 | 2 = 10 | 3+ = 20 | emergency request = 30 | G6: =INDEX('Indicator Master'!$N$4:$N$46,MATCH($A6,'Indicator Master'!$A$4:$A$46,0)) -> 30 | H6: Raw Score = score of the single band whose condition the borrower value satisfies; 0 if none is breached. | I6: Normalised = Raw ÷ Max Score × 100 (0–100). Fed into the Overall Score Engine.
A7: EWS-003 | B7: Monthly sales vs credit summation | C7: EWS | D7: Reduction in monthly credits in operating account | E7: CreditChange% = (CurrentMonthCredits - Baseline)/Baseline | F7: Stable/Variation upto 5% = 0 | 5-10% decline = 10 | 10-15% decline = 20 | >15% = 35 | G7: =INDEX('Indicator Master'!$N$4:$N$46,MATCH($A7,'Indicator Master'!$A$4:$A$46,0)) -> 35 | H7: Raw Score = score of the single band whose condition the borrower value satisfies; 0 if none is breached. | I7: Normalised = Raw ÷ Max Score × 100 (0–100). Fed into the Overall Score Engine.
A8: EWS-004 | B8: Payment Default Frequency | C8: EWS | D8: Cheque returns, Cheque Bounce, ECS bounce, frequent TODs | E8: Compute Count of conduct events (rolling 90d) then compare to threshold bands | F8: 0 = 0 | 1 = 5 | 2 = 15 | 3+ in 90 days = 25 | G8: =INDEX('Indicator Master'!$N$4:$N$46,MATCH($A8,'Indicator Master'!$A$4:$A$46,0)) -> 25 | H8: Raw Score = score of the single band whose condition the borrower value satisfies; 0 if none is breached. | I8: Normalised = Raw ÷ Max Score × 100 (0–100). Fed into the Overall Score Engine.
A9: EWS-005 | B9: Repayment source classification | C9: EWS | D9: Repayment from unrelated parties or group accounts | E9: Classify event severity for 'Change in repayment source' (no numeric calc) | F9: Own operating cash flow = 0 | group support = 15 | unrelated source = 30 | repeated third-party payments = 40 | G9: =INDEX('Indicator Master'!$N$4:$N$46,MATCH($A9,'Indicator Master'!$A$4:$A$46,0)) -> 40 | H9: Raw Score = score of the single band whose condition the borrower value satisfies; 0 if none is breached. | I9: Normalised = Raw ÷ Max Score × 100 (0–100). Fed into the Overall Score Engine.
A10: EWS-006 | B10: Stock reported vs audited variance % | C10: EWS | D10: Difference between reported stock and audited numbers | E10: Compute Stock reported vs audited variance % then compare to threshold bands | F10: 0% variance = 0 | upto 10% = 10 | upto 20% = 20 | >20% = 30 | G10: =INDEX('Indicator Master'!$N$4:$N$46,MATCH($A10,'Indicator Master'!$A$4:$A$46,0)) -> 30 | H10: Raw Score = score of the single band whose condition the borrower value satisfies; 0 if none is breached. | I10: Normalised = Raw ÷ Max Score × 100 (0–100). Fed into the Overall Score Engine.
A11: EWS-007 | B11: Sales turnover YoY/QoQ change % | C11: EWS | D11: Monthly/quarterly sales drop | E11: SalesChange% vs prior comparable period | F11: Stable/Variation upto 5% = 0 | 5-10% decline = 10 | 10-15% decline = 20 | >15% = 35 | G11: =INDEX('Indicator Master'!$N$4:$N$46,MATCH($A11,'Indicator Master'!$A$4:$A$46,0)) -> 35 | H11: Raw Score = score of the single band whose condition the borrower value satisfies; 0 if none is breached. | I11: Normalised = Raw ÷ Max Score × 100 (0–100). Fed into the Overall Score Engine.
A12: EWS-008 | B12: EBITDA margin change % | C12: EWS | D12: EBITDA margin falling over periods | E12: Compute EBITDA margin change % then compare to threshold bands | F12: Stable/Variation upto 5% = 0 | 5-10% decline = 10 | 10-15% decline = 20 | >15% = 35 | G12: =INDEX('Indicator Master'!$N$4:$N$46,MATCH($A12,'Indicator Master'!$A$4:$A$46,0)) -> 35 | H12: Raw Score = score of the single band whose condition the borrower value satisfies; 0 if none is breached. | I12: Normalised = Raw ÷ Max Score × 100 (0–100). Fed into the Overall Score Engine.
A13: EWS-009 | B13: Debtor days vs normal | C13: EWS | D13: Receivable days increasing sharply | E13: DebtorDaysDelta = DebtorDays - Normal | F13: Within normal = 0 | upto 10 days = 10 | 10-20 days = 20 | >20 days = 30 | G13: =INDEX('Indicator Master'!$N$4:$N$46,MATCH($A13,'Indicator Master'!$A$4:$A$46,0)) -> 30 | H13: Raw Score = score of the single band whose condition the borrower value satisfies; 0 if none is breached. | I13: Normalised = Raw ÷ Max Score × 100 (0–100). Fed into the Overall Score Engine.
A14: EWS-010 | B14: Inventory days vs normal | C14: EWS | D14: Inventory holding period increasing | E14: Compute Inventory days vs normal (delta days) then compare to threshold bands | F14: Within normal = 0 | +15-30 days = 10 | +30-60 days = 20 | +60 days = 30 | G14: =INDEX('Indicator Master'!$N$4:$N$46,MATCH($A14,'Indicator Master'!$A$4:$A$46,0)) -> 30 | H14: Raw Score = score of the single band whose condition the borrower value satisfies; 0 if none is breached. | I14: Normalised = Raw ÷ Max Score × 100 (0–100). Fed into the Overall Score Engine.
A15: EWS-011 | B15: Creditor days vs normal | C15: EWS | D15: Payables increasing beyond normal cycle | E15: Compute Creditor days vs normal (delta days) then compare to threshold bands | F15: Within normal = 0 | +15-30 days = 10 | +30-60 days = 20 | +60 days = 30 | G15: =INDEX('Indicator Master'!$N$4:$N$46,MATCH($A15,'Indicator Master'!$A$4:$A$46,0)) -> 30 | H15: Raw Score = score of the single band whose condition the borrower value satisfies; 0 if none is breached. | I15: Normalised = Raw ÷ Max Score × 100 (0–100). Fed into the Overall Score Engine.
A16: EWS-012 | B16: Provisions/write-offs change % | C16: EWS | D16: Increase in bad debts / provisions | E16: Compute Provisions/write-offs change % then compare to threshold bands | F16: ≤ 10% increase = 0 | >10% to 25% increase = 15 | >25% to 50% increase = 30 | >50% increase = 40 | G16: =INDEX('Indicator Master'!$N$4:$N$46,MATCH($A16,'Indicator Master'!$A$4:$A$46,0)) -> 40 | H16: Raw Score = score of the single band whose condition the borrower value satisfies; 0 if none is breached. | I16: Normalised = Raw ÷ Max Score × 100 (0–100). Fed into the Overall Score Engine.
... A47: EWS-043 | B47: Current Ratio | C47: EWS | D47: Current ratio | E47: Current Assets / Current Liabilities | F47: ≥1.33 = 0 | 1–1.33 = 10 | <1.00 = 40 | G47: =INDEX('Indicator Master'!$N$4:$N$46,MATCH($A47,'Indicator Master'!$A$4:$A$46,0)) -> 40 | H47: Raw Score = score of the single band whose condition the borrower value satisfies; 0 if none is breached. | I47: Normalised = Raw ÷ Max Score × 100 (0–100). Fed into the Overall Score Engine.

Sheet Scoring Engine (Rules)
A1: Threshold & Scoring Engine — Machine-Readable Rules + Remedial Playbook
A2: One row per band. Rule Type/Lower/Upper/Operator are data-type driven; Normalised@Band & Is-Max are live; key = UID|Raw.
A4: UID | B4: Indicator | C4: Module | D4: Metric / Input | E4: Band Order | F4: Condition (verbatim) | G4: Rule Type | H4: Lower Bound | I4: Upper Bound | J4: Operator | K4: Raw Score | L4: Normalised @ Band | M4: Is Max Band | N4: Critical Event Flag | O4: What it signals & likely drivers | P4: Remedial action plan (step-by-step) | Q4: Primary owner | R4: key (helper)
A5: EWS-001 | B5: Utilization % (outstanding / sanctioned) | C5: EWS | D5: CC/OD utilization above 85-90% continuously | E5: 1 | F5: <85% | G5: Percent Threshold | I5: 85 | J5: < upper | K5: 0 | L5: =$K5/INDEX('Indicator Master'!$N$4:$N$46,MATCH($A5,'Indicator Master'!$A$4:$A$46,0))*'Risk Bands (Config)'!$B$5 -> 0 | M5: =IF($K5=INDEX('Indicator Master'!$N$4:$N$46,MATCH($A5,'Indicator Master'!$A$4:$A$46,0)),1,0) -> 0 | O5: Normal — utilisation below 85%; comfortable headroom on working-capital limits. | P5: No remedial action required. Continue routine monitoring at the standard review cycle and record the reading. | Q5: RM (routine) | R5: =$A5&"|"&$K5 -> EWS-001|0
A6: EWS-001 | B6: Utilization % (outstanding / sanctioned) | C6: EWS | D6: CC/OD utilization above 85-90% continuously | E6: 2 | F6: 85-90% | G6: Percent Range | H6: 85 | I6: 90 | J6: ≥ lower & < upper | K6: 10 | L6: =$K6/INDEX('Indicator Master'!$N$4:$N$46,MATCH($A6,'Indicator Master'!$A$4:$A$46,0))*'Risk Bands (Config)'!$B$5 -> 33.333333 | M6: =IF($K6=INDEX('Indicator Master'!$N$4:$N$46,MATCH($A6,'Indicator Master'!$A$4:$A$46,0)),1,0) -> 0 | O6: Early warning — utilisation 85–90%; mild tightening, usually genuine sales/WC growth or a seasonal build-up. | P6: 1) RM to confirm the cause (seasonal vs structural). 2) Check stock/receivables statements support the drawings. 3) Flag for the next review. | Q6: RM + Credit Analyst | R6: =$A6&"|"&$K6 -> EWS-001|10
A7: EWS-001 | B7: Utilization % (outstanding / sanctioned) | C7: EWS | D7: CC/OD utilization above 85-90% continuously | E7: 3 | F7: 90-95% | G7: Percent Range | H7: 90 | I7: 95 | J7: ≥ lower & < upper | K7: 20 | L7: =$K7/INDEX('Indicator Master'!$N$4:$N$46,MATCH($A7,'Indicator Master'!$A$4:$A$46,0))*'Risk Bands (Config)'!$B$5 -> 66.666667 | M7: =IF($K7=INDEX('Indicator Master'!$N$4:$N$46,MATCH($A7,'Indicator Master'!$A$4:$A$46,0)),1,0) -> 0 | O7: Elevated concern — utilisation 90–95% sustained; limits may be inadequate or the WC cycle is stretching (slow debtors/inventory). | P7: 1) Reassess the WC assessment and drawing power on updated financials. 2) Verify no diversion via a turnover-routing check. 3) Move to monthly monitoring; consider a limit review. | Q7: Credit Committee / Zonal Credit | R7: =$A7&"|"&$K7 -> EWS-001|20
A8: EWS-001 | B8: Utilization % (outstanding / sanctioned) | C8: EWS | D8: CC/OD utilization above 85-90% continuously | E8: 4 | F8: >95% for 30+ days | G8: Percent Threshold | H8: 95 | J8: ≥ lower (sustained 30+ days) | K8: 30 | L8: =$K8/INDEX('Indicator Master'!$N$4:$N$46,MATCH($A8,'Indicator Master'!$A$4:$A$46,0))*'Risk Bands (Config)'!$B$5 -> 100 | M8: =IF($K8=INDEX('Indicator Master'!$N$4:$N$46,MATCH($A8,'Indicator Master'!$A$4:$A$46,0)),1,0) -> 1 | O8: Severe / critical — utilisation above 95% for 30+ days; chronic over-reliance — possible inability to rotate WC, or diversion/ever-greening. | P8: 1) Restrict fresh drawals pending review. 2) Investigate diversion (routing gaps, ad-hoc pattern). 3) Full viability / limit-rationalisation review; escalate to Credit. | Q8: Credit Head / Risk | R8: =$A8&"|"&$K8 -> EWS-001|30
A9: EWS-002 | B9: Count of ad-hoc limit requests (rolling 12m) | C9: EWS | D9: Temporary limit enhancement requests | E9: 1 | F9: 0-1 request/year | G9: Count Range | H9: 0 | I9: 1 | J9: ≥ lower & ≤ upper | K9: 0 | L9: =$K9/INDEX('Indicator Master'!$N$4:$N$46,MATCH($A9,'Indicator Master'!$A$4:$A$46,0))*'Risk Bands (Config)'!$B$5 -> 0 | M9: =IF($K9=INDEX('Indicator Master'!$N$4:$N$46,MATCH($A9,'Indicator Master'!$A$4:$A$46,0)),1,0) -> 0 | O9: Normal — at most one ad-hoc request in the year; no pattern. | P9: No remedial action required. Continue routine monitoring at the standard review cycle and record the reading. | Q9: RM (routine) | R9: =$A9&"|"&$K9 -> EWS-002|0
A10: EWS-002 | B10: Count of ad-hoc limit requests (rolling 12m) | C10: EWS | D10: Temporary limit enhancement requests | E10: 2 | F10: 2 | G10: Count Exact | H10: 2 | I10: 2 | J10: exactly = value | K10: 10 | L10: =$K10/INDEX('Indicator Master'!$N$4:$N$46,MATCH($A10,'Indicator Master'!$A$4:$A$46,0))*'Risk Bands (Config)'!$B$5 -> 33.333333 | M10: =IF($K10=INDEX('Indicator Master'!$N$4:$N$46,MATCH($A10,'Indicator Master'!$A$4:$A$46,0)),1,0) -> 0 | O10: Early warning — two ad-hoc requests; occasional cash-flow mismatch. | P10: 1) Ascertain the reason for each request. 2) Check whether permanent WC is under-assessed. 3) Grant only against a documented need. | Q10: RM + Credit Analyst | R10: =$A10&"|"&$K10 -> EWS-002|10
A11: EWS-002 | B11: Count of ad-hoc limit requests (rolling 12m) | C11: EWS | D11: Temporary limit enhancement requests | E11: 3 | F11: 3+ | G11: Count Threshold | H11: 3 | J11: ≥ lower | K11: 20 | L11: =$K11/INDEX('Indicator Master'!$N$4:$N$46,MATCH($A11,'Indicator Master'!$A$4:$A$46,0))*'Risk Bands (Config)'!$B$5 -> 66.666667 | M11: =IF($K11=INDEX('Indicator Master'!$N$4:$N$46,MATCH($A11,'Indicator Master'!$A$4:$A$46,0)),1,0) -> 0 | O11: Elevated concern — three or more ad-hoc requests; recurring liquidity gaps suggest a structural WC shortfall. | P11: 1) Reassess permanent WC limits versus turnover. 2) Decline routine ad-hocs; require promoter funds for genuine gaps. 3) Tighten conduct review. | Q11: Credit Committee / Zonal Credit | R11: =$A11&"|"&$K11 -> EWS-002|20
A12: EWS-002 | B12: Count of ad-hoc limit requests (rolling 12m) | C12: EWS | D12: Temporary limit enhancement requests | E12: 4 | F12: emergency request | G12: Event flag | J12: category | K12: 30 | L12: =$K12/INDEX('Indicator Master'!$N$4:$N$46,MATCH($A12,'Indicator Master'!$A$4:$A$46,0))*'Risk Bands (Config)'!$B$5 -> 100 | M12: =IF($K12=INDEX('Indicator Master'!$N$4:$N$46,MATCH($A12,'Indicator Master'!$A$4:$A$46,0)),1,0) -> 1 | O12: Severe / critical — an emergency / out-of-cycle request; acute liquidity stress. | P12: 1) Treat as a stress trigger; obtain an immediate cash-flow statement. 2) Do not fund without security/comfort. 3) Escalate to Credit. | Q12: Credit Head / Risk | R12: =$A12&"|"&$K12 -> EWS-002|30
A13: EWS-003 | B13: Monthly sales vs credit summation | C13: EWS | D13: Reduction in monthly credits in operating account | E13: 1 | F13: Stable/Variation upto 5% | G13: Percent Threshold | I13: 5 | J13: < upper | K13: 0 | L13: =$K13/INDEX('Indicator Master'!$N$4:$N$46,MATCH($A13,'Indicator Master'!$A$4:$A$46,0))*'Risk Bands (Config)'!$B$5 -> 0 | M13: =IF($K13=INDEX('Indicator Master'!$N$4:$N$46,MATCH($A13,'Indicator Master'!$A$4:$A$46,0)),1,0) -> 0 | O13: Normal — operating-account credits stable or rising; sales routing intact. | P13: No remedial action required. Continue routine monitoring at the standard review cycle and record the reading. | Q13: RM (routine) | R13: =$A13&"|"&$K13 -> EWS-003|0
A14: EWS-003 | B14: Monthly sales vs credit summation | C14: EWS | D14: Reduction in monthly credits in operating account | E14: 2 | F14: 5-10% decline | G14: Percent Range | H14: 5 | I14: 10 | J14: ≥ lower & < upper | K14: 10 | L14: =$K14/INDEX('Indicator Master'!$N$4:$N$46,MATCH($A14,'Indicator Master'!$A$4:$A$46,0))*'Risk Bands (Config)'!$B$5 -> 28.571429 | M14: =IF($K14=INDEX('Indicator Master'!$N$4:$N$46,MATCH($A14,'Indicator Master'!$A$4:$A$46,0)),1,0) -> 0 | O14: Early warning — credits down 10–20% vs baseline; early softening or partial routing to another bank. | P14: 1) Reconcile account credits to GST/sales. 2) Ask the RM whether routing has shifted. 3) Note the trend for next review. | Q14: Relationship Manager (Branch) | R14: =$A14&"|"&$K14 -> EWS-003|10
A15: EWS-003 | B15: Monthly sales vs credit summation | C15: EWS | D15: Reduction in monthly credits in operating account | E15: 3 | F15: 10-15% decline | G15: Percent Range | H15: 10 | I15: 15 | J15: ≥ lower & < upper | K15: 20 | L15: =$K15/INDEX('Indicator Master'!$N$4:$N$46,MATCH($A15,'Indicator Master'!$A$4:$A$46,0))*'Risk Bands (Config)'!$B$5 -> 57.142857 | M15: =IF($K15=INDEX('Indicator Master'!$N$4:$N$46,MATCH($A15,'Indicator Master'!$A$4:$A$46,0)),1,0) -> 0 | O15: Elevated concern — credits down 20–40%; material drop — genuine sales fall or turnover being diverted elsewhere. | P15: 1) Stipulate proportionate turnover routing through the bank. 2) Verify sales via GST returns. 3) Monitor monthly credits vs sales. | Q15: RM + Credit Analyst | R15: =$A15&"|"&$K15 -> EWS-003|20
A16: EWS-003 | B16: Monthly sales vs credit summation | C16: EWS | D16: Reduction in monthly credits in operating account | E16: 4 | F16: >15% decline | G16: Percent Threshold | H16: 15 | J16: > lower | K16: 35 | L16: =$K16/INDEX('Indicator Master'!$N$4:$N$46,MATCH($A16,'Indicator Master'!$A$4:$A$46,0))*'Risk Bands (Config)'!$B$5 -> 100 | M16: =IF($K16=INDEX('Indicator Master'!$N$4:$N$46,MATCH($A16,'Indicator Master'!$A$4:$A$46,0)),1,0) -> 1 | N16: CRITICAL EVENT | O16: Severe / critical — credits down >40%; severe — likely sales collapse or systematic diversion of turnover. | P16: 1) Investigate diversion to other lenders; consider an escrow / TRA mechanism. 2) Commission an end-use/turnover audit. 3) Escalate to Credit; recall if diversion confirmed. | Q16: Credit Head / Risk / Fraud | R16: =$A16&"|"&$K16 -> EWS-003|35
A17: EWS-004 | B17: Payment Default Frequency | C17: EWS | D17: Cheque returns, Cheque Bounce, ECS bounce, frequent TODs | E17: 1 | F17: 0 | G17: Count Exact | H17: 0 | I17: 0 | J17: exactly = value | K17: 0 | L17: =$K17/INDEX('Indicator Master'!$N$4:$N$46,MATCH($A17,'Indicator Master'!$A$4:$A$46,0))*'Risk Bands (Config)'!$B$5 -> 0 | M17: =IF($K17=INDEX('Indicator Master'!$N$4:$N$46,MATCH($A17,'Indicator Master'!$A$4:$A$46,0)),1,0) -> 0 | O17: Normal — no conduct events in the window; clean account behaviour. | P17: No remedial action required. Continue routine monitoring at the standard review cycle and record the reading. | Q17: RM (routine) | R17: =$A17&"|"&$K17 -> EWS-004|0
A18: EWS-004 | B18: Payment Default Frequency | C18: EWS | D18: Cheque returns, Cheque Bounce, ECS bounce, frequent TODs | E18: 2 | F18: 1 | G18: Count Exact | H18: 1 | I18: 1 | J18: exactly = value | K18: 5 | L18: =$K18/INDEX('Indicator Master'!$N$4:$N$46,MATCH($A18,'Indicator Master'!$A$4:$A$46,0))*'Risk Bands (Config)'!$B$5 -> 20 | M18: =IF($K18=INDEX('Indicator Master'!$N$4:$N$46,MATCH($A18,'Indicator Master'!$A$4:$A$46,0)),1,0) -> 0 | O18: Early warning — one conduct event; isolated slip, likely a timing mismatch. | P18: 1) Note the event and reason. 2) Caution the borrower informally. 3) Watch the next cycle. | Q18: Relationship Manager (Branch) | R18: =$A18&"|"&$K18 -> EWS-004|5
A19: EWS-004 | B19: Payment Default Frequency | C19: EWS | D19: Cheque returns, Cheque Bounce, ECS bounce, frequent TODs | E19: 3 | F19: 2 | G19: Count Exact | H19: 2 | I19: 2 | J19: exactly = value | K19: 15 | L19: =$K19/INDEX('Indicator Master'!$N$4:$N$46,MATCH($A19,'Indicator Master'!$A$4:$A$46,0))*'Risk Bands (Config)'!$B$5 -> 60 | M19: =IF($K19=INDEX('Indicator Master'!$N$4:$N$46,MATCH($A19,'Indicator Master'!$A$4:$A$46,0)),1,0) -> 0 | O19: Elevated concern — two conduct events; a pattern is forming — recurring liquidity or discipline issue. | P19: 1) Obtain a written explanation. 2) Enforce due-date discipline / standing instructions. 3) Place on the watch-list. | Q19: RM + Credit Analyst | R19: =$A19&"|"&$K19 -> EWS-004|15
A20: EWS-004 | B20: Payment Default Frequency | C20: EWS | D20: Cheque returns, Cheque Bounce, ECS bounce, frequent TODs | E20: 4 | F20: 3+ in 90 days | G20: Count Threshold | H20: 3 | J20: ≥ lower | K20: 25 | L20: =$K20/INDEX('Indicator Master'!$N$4:$N$46,MATCH($A20,'Indicator Master'!$A$4:$A$46,0))*'Risk Bands (Config)'!$B$5 -> 100 | M20: =IF($K20=INDEX('Indicator Master'!$N$4:$N$46,MATCH($A20,'Indicator Master'!$A$4:$A$46,0)),1,0) -> 1 | O20: Severe / critical — three or more events in 90 days; persistent irregularity signalling stress. | P20: 1) Treat as incipient stress; SMA tagging as per days. 2) Obtain a corrective cash-flow plan. 3) Escalate to Credit; review provisioning. | Q20: Credit Head / Risk | R20: =$A20&"|"&$K20 -> EWS-004|25
A21: EWS-005 | B21: Repayment source classification | C21: EWS | D21: Repayment from unrelated parties or group accounts | E21: 1 | F21: Own operating cash flow | G21: Ordinal Classification | J21: category | K21: 0 | L21: =$K21/INDEX('Indicator Master'!$N$4:$N$46,MATCH($A21,'Indicator Master'!$A$4:$A$46,0))*'Risk Bands (Config)'!$B$5 -> 0 | M21: =IF($K21=INDEX('Indicator Master'!$N$4:$N$46,MATCH($A21,'Indicator Master'!$A$4:$A$46,0)),1,0) -> 0 | O21: Normal — repayments from the borrower's own operating cash flows; healthy. | P21: No remedial action required. Continue routine monitoring at the standard review cycle and record the reading. | Q21: RM (routine) | R21: =$A21&"|"&$K21 -> EWS-005|0
A22: EWS-005 | B22: Repayment source classification | C22: EWS | D22: Repayment from unrelated parties or group accounts | E22: 2 | F22: group support | G22: Ordinal Classification | J22: category | K22: 15 | L22: =$K22/INDEX('Indicator Master'!$N$4:$N$46,MATCH($A22,'Indicator Master'!$A$4:$A$46,0))*'Risk Bands (Config)'!$B$5 -> 37.5 | M22: =IF($K22=INDEX('Indicator Master'!$N$4:$N$46,MATCH($A22,'Indicator Master'!$A$4:$A$46,0)),1,0) -> 0 | O22: Elevated concern — repayments supported by group funds; servicing not fully self-generated. | P22: 1) Question reliance on group support; assess standalone viability. 2) Seek an undertaking on the arrangement. 3) Monitor. | Q22: RM + Credit Analyst | R22: =$A22&"|"&$K22 -> EWS-005|15
A23: EWS-005 | B23: Repayment source classification | C23: EWS | D23: Repayment from unrelated parties or group accounts | E23: 3 | F23: unrelated source | G23: Ordinal Classification | J23: category | K23: 30 | L23: =$K23/INDEX('Indicator Master'!$N$4:$N$46,MATCH($A23,'Indicator Master'!$A$4:$A$46,0))*'Risk Bands (Config)'!$B$5 -> 75 | M23: =IF($K23=INDEX('Indicator Master'!$N$4:$N$46,MATCH($A23,'Indicator Master'!$A$4:$A$46,0)),1,0) -> 0 | O23: High concern — repayments from an unrelated/third-party source; questionable sustainability. | P23: 1) Investigate the third-party source and fund flow. 2) Reassess viability and repayment capacity. 3) Tighten; escalate to Credit. | Q23: Credit + Risk | R23: =$A23&"|"&$K23 -> EWS-005|30
A24: EWS-005 | B24: Repayment source classification | C24: EWS | D24: Repayment from unrelated parties or group accounts | E24: 4 | F24: repeated third-party payments | G24: Ordinal Classification | J24: category | K24: 40 | L24: =$K24/INDEX('Indicator Master'!$N$4:$N$46,MATCH($A24,'Indicator Master'!$A$4:$A$46,0))*'Risk Bands (Config)'!$B$5 -> 100 | M24: =IF($K24=INDEX('Indicator Master'!$N$4:$N$46,MATCH($A24,'Indicator Master'!$A$4:$A$46,0)),1,0) -> 1 | O24: Severe / critical — repeated third-party payments; classic ever-greening / round-tripping risk. | P24: 1) Treat as suspected ever-greening; order a fund-flow/forensic review. 2) Freeze incremental exposure. 3) Escalate for corrective / exit action. | Q24: Credit Head / Risk / Fraud | R24: =$A24&"|"&$K24 -> EWS-005|40
A25: EWS-006 | B25: Stock reported vs audited variance % | C25: EWS | D25: Difference between reported stock and audited numbers | E25: 1 | F25: 0% variance | G25: Percent Threshold | I25: 0 | J25: ≤ upper | K25: 0 | L25: =$K25/INDEX('Indicator Master'!$N$4:$N$46,MATCH($A25,'Indicator Master'!$A$4:$A$46,0))*'Risk Bands (Config)'!$B$5 -> 0 | M25: =IF($K25=INDEX('Indicator Master'!$N$4:$N$46,MATCH($A25,'Indicator Master'!$A$4:$A$46,0)),1,0) -> 0 | O25: Normal — no variance between reported and audited stock; reliable reporting. | P25: No remedial action required. Continue routine monitoring at the standard review cycle and record the reading. | Q25: RM (routine) | R25: =$A25&"|"&$K25 -> EWS-006|0
A26: EWS-006 | B26: Stock reported vs audited variance % | C26: EWS | D26: Difference between reported stock and audited numbers | E26: 2 | F26: upto 10% | G26: Percent Range | H26: 0 | I26: 10 | J26: > lower & ≤ upper | K26: 10 | L26: =$K26/INDEX('Indicator Master'!$N$4:$N$46,MATCH($A26,'Indicator Master'!$A$4:$A$46,0))*'Risk Bands (Config)'!$B$5 -> 33.333333 | M26: =IF($K26=INDEX('Indicator Master'!$N$4:$N$46,MATCH($A26,'Indicator Master'!$A$4:$A$46,0)),1,0) -> 0 | O26: Early warning — up to 10% variance; minor reconciliation gap, likely timing or method. | P26: 1) Reconcile the statement to audited figures. 2) Seek clarification on the small gap. | Q26: RM + Credit Analyst | R26: =$A26&"|"&$K26 -> EWS-006|10
A27: EWS-006 | B27: Stock reported vs audited variance % | C27: EWS | D27: Difference between reported stock and audited numbers | E27: 3 | F27: upto 20% | G27: Percent Range | H27: 10 | I27: 20 | J27: > lower & ≤ upper | K27: 20 | L27: =$K27/INDEX('Indicator Master'!$N$4:$N$46,MATCH($A27,'Indicator Master'!$A$4:$A$46,0))*'Risk Bands (Config)'!$B$5 -> 66.666667 | M27: =IF($K27=INDEX('Indicator Master'!$N$4:$N$46,MATCH($A27,'Indicator Master'!$A$4:$A$46,0)),1,0) -> 0 | O27: Elevated concern — 10–20% variance; material overstatement of DP securities emerging. | P27: 1) Order a stock/receivables audit. 2) Recompute drawing power on verified stock. 3) Monitor. | Q27: Credit Committee / Zonal Credit | R27: =$A27&"|"&$K27 -> EWS-006|20
A28: EWS-006 | B28: Stock reported vs audited variance % | C28: EWS | D28: Difference between reported stock and audited numbers | E28: 4 | F28: >20% | G28: Percent Threshold | H28: 20 | J28: > lower | K28: 30 | L28: =$K28/INDEX('Indicator Master'!$N$4:$N$46,MATCH($A28,'Indicator Master'!$A$4:$A$46,0))*'Risk Bands (Config)'!$B$5 -> 100 | M28: =IF($K28=INDEX('Indicator Master'!$N$4:$N$46,MATCH($A28,'Indicator Master'!$A$4:$A$46,0)),1,0) -> 1 | O28: Severe / critical — >20% variance; large overstatement — inflated drawing power / possible window-dressing. | P28: 1) Commission an independent stock audit; correct the DP. 2) Reduce limits to the corrected DP. 3) Treat inflated DP as diversion risk; escalate to Credit. | Q28: Credit Head / Risk | R28: =$A28&"|"&$K28 -> EWS-006|30
A29: EWS-007 | B29: Sales turnover YoY/QoQ change % | C29: EWS | D29: Monthly/quarterly sales drop | E29: 1 | F29: Stable/Variation upto 5% | G29: Percent Threshold | I29: 5 | J29: < upper | K29: 0 | L29: =$K29/INDEX('Indicator Master'!$N$4:$N$46,MATCH($A29,'Indicator Master'!$A$4:$A$46,0))*'Risk Bands (Config)'!$B$5 -> 0 | M29: =IF($K29=INDEX('Indicator Master'!$N$4:$N$46,MATCH($A29,'Indicator Master'!$A$4:$A$46,0)),1,0) -> 0 | O29: Normal — turnover stable or growing; demand intact. | P29: No remedial action required. Continue routine monitoring at the standard review cycle and record the reading. | Q29: RM (routine) | R29: =$A29&"|"&$K29 -> EWS-007|0
A30: EWS-007 | B30: Sales turnover YoY/QoQ change % | C30: EWS | D30: Monthly/quarterly sales drop | E30: 2 | F30: 5-10% decline | G30: Percent Range | H30: 5 | I30: 10 | J30: ≥ lower & < upper | K30: 10 | L30: =$K30/INDEX('Indicator Master'!$N$4:$N$46,MATCH($A30,'Indicator Master'!$A$4:$A$46,0))*'Risk Bands (Config)'!$B$5 -> 28.571429 | M30: =IF($K30=INDEX('Indicator Master'!$N$4:$N$46,MATCH($A30,'Indicator Master'!$A$4:$A$46,0)),1,0) -> 0 | O30: Early warning — turnover down 10–20%; early demand softening or a one-off. | P30: 1) Reassess projections and the WC cycle. 2) RM engagement; management action note. 3) Monthly review. | Q30: Relationship Manager (Branch) | R30: =$A30&"|"&$K30 -> EWS-007|10
A31: EWS-007 | B31: Sales turnover YoY/QoQ change % | C31: EWS | D31: Monthly/quarterly sales drop | E31: 3 | F31: 10-15% decline | G31: Percent Range | H31: 10 | I31: 15 | J31: ≥ lower & < upper | K31: 20 | L31: =$K31/INDEX('Indicator Master'!$N$4:$N$46,MATCH($A31,'Indicator Master'!$A$4:$A$46,0))*'Risk Bands (Config)'!$B$5 -> 57.142857 | M31: =IF($K31=INDEX('Indicator Master'!$N$4:$N$46,MATCH($A31,'Indicator Master'!$A$4:$A$46,0)),1,0) -> 0 | O31: Elevated concern — turnover down 20–40%; a genuine downturn or loss of key customers. | P31: 1) Reassess repayment capacity and viability with a sensitivity run. 2) Consider whether restructuring is needed. 3) Escalate to Credit. | Q31: RM + Credit Analyst | R31: =$A31&"|"&$K31 -> EWS-007|20
A32: EWS-007 | B32: Sales turnover YoY/QoQ change % | C32: EWS | D32: Monthly/quarterly sales drop | E32: 4 | F32: >15% decline | G32: Percent Threshold | H32: 15 | J32: > lower | K32: 35 | L32: =$K32/INDEX('Indicator Master'!$N$4:$N$46,MATCH($A32,'Indicator Master'!$A$4:$A$46,0))*'Risk Bands (Config)'!$B$5 -> 100 | M32: =IF($K32=INDEX('Indicator Master'!$N$4:$N$46,MATCH($A32,'Indicator Master'!$A$4:$A$46,0)),1,0) -> 1 | N32: CRITICAL EVENT | O32: Severe / critical — turnover down >40% or a loss; severe demand/operational deterioration. | P32: 1) Full viability / TEV review. 2) Assess restructuring / rephasement. 3) Provisioning review; escalate to Credit Committee. | Q32: Credit Head / Risk | R32: =$A32&"|"&$K32 -> EWS-007|35
A33: EWS-008 | B33: EBITDA margin change % | C33: EWS | D33: EBITDA margin falling over periods | E33: 1 | F33: Stable/Variation upto 5% | G33: Percent Threshold | I33: 5 | J33: < upper | K33: 0 | L33: =$K33/INDEX('Indicator Master'!$N$4:$N$46,MATCH($A33,'Indicator Master'!$A$4:$A$46,0))*'Risk Bands (Config)'!$B$5 -> 0 | M33: =IF($K33=INDEX('Indicator Master'!$N$4:$N$46,MATCH($A33,'Indicator Master'!$A$4:$A$46,0)),1,0) -> 0 | O33: Normal — EBITDA margin stable; profitability intact. | P33: No remedial action required. Continue routine monitoring at the standard review cycle and record the reading. | Q33: RM (routine) | R33: =$A33&"|"&$K33 -> EWS-008|0
A34: EWS-008 | B34: EBITDA margin change % | C34: EWS | D34: EBITDA margin falling over periods | E34: 2 | F34: 5-10% decline | G34: Percent Range | H34: 5 | I34: 10 | J34: ≥ lower & < upper | K34: 10 | L34: =$K34/INDEX('Indicator Master'!$N$4:$N$46,MATCH($A34,'Indicator Master'!$A$4:$A$46,0))*'Risk Bands (Config)'!$B$5 -> 28.571429 | M34: =IF($K34=INDEX('Indicator Master'!$N$4:$N$46,MATCH($A34,'Indicator Master'!$A$4:$A$46,0)),1,0) -> 0 | O34: Early warning — margin fell 10–20%; cost inflation or pricing pressure beginning. | P34: 1) Analyse cost vs price drivers. 2) Reassess DSCR on updated numbers. 3) Monitor. | Q34: Relationship Manager (Branch) | R34: =$A34&"|"&$K34 -> EWS-008|10
A35: EWS-008 | B35: EBITDA margin change % | C35: EWS | D35: EBITDA margin falling over periods | E35: 3 | F35: 10-15% decline | G35: Percent Range | H35: 10 | I35: 15 | J35: ≥ lower & < upper | K35: 20 | L35: =$K35/INDEX('Indicator Master'!$N$4:$N$46,MATCH($A35,'Indicator Master'!$A$4:$A$46,0))*'Risk Bands (Config)'!$B$5 -> 57.142857 | M35: =IF($K35=INDEX('Indicator Master'!$N$4:$N$46,MATCH($A35,'Indicator Master'!$A$4:$A$46,0)),1,0) -> 0 | O35: Elevated concern — margin fell 20–40%; material erosion of debt-servicing ability. | P35: 1) Reassess repayment capacity and viability. 2) Enhanced monitoring. 3) Escalate to Credit. | Q35: RM + Credit Analyst | R35: =$A35&"|"&$K35 -> EWS-008|20
A36: EWS-008 | B36: EBITDA margin change % | C36: EWS | D36: EBITDA margin falling over periods | E36: 4 | F36: >15% decline | G36: Percent Threshold | H36: 15 | J36: ≥ lower (or loss) | K36: 35 | L36: =$K36/INDEX('Indicator Master'!$N$4:$N$46,MATCH($A36,'Indicator Master'!$A$4:$A$46,0))*'Risk Bands (Config)'!$B$5 -> 100 | M36: =IF($K36=INDEX('Indicator Master'!$N$4:$N$46,MATCH($A36,'Indicator Master'!$A$4:$A$46,0)),1,0) -> 1 | O36: Severe / critical — margin fell >40% or turned to a loss; severe profitability collapse. | P36: 1) Full viability review; assess restructuring. 2) Provisioning review. 3) Escalate to Credit Committee. | Q36: Credit Head / Risk | R36: =$A36&"|"&$K36 -> EWS-008|35
A37: EWS-009 | B37: Debtor days vs normal | C37: EWS | D37: Receivable days increasing sharply | E37: 1 | F37: Within normal | G37: Delta Days Threshold | H37: 0 | I37: 0 | J37: exactly = value | K37: 0 | L37: =$K37/INDEX('Indicator Master'!$N$4:$N$46,MATCH($A37,'Indicator Master'!$A$4:$A$46,0))*'Risk Bands (Config)'!$B$5 -> 0 | M37: =IF($K37=INDEX('Indicator Master'!$N$4:$N$46,MATCH($A37,'Indicator Master'!$A$4:$A$46,0)),1,0) -> 0 | O37: Normal — debtor days within norm; receivables turning normally. | P37: No remedial action required. Continue routine monitoring at the standard review cycle and record the reading. | Q37: RM (routine) | R37: =$A37&"|"&$K37 -> EWS-009|0
A38: EWS-009 | B38: Debtor days vs normal | C38: EWS | D38: Receivable days increasing sharply | E38: 2 | F38: upto 10 days | G38: Delta Days Threshold | I38: 10 | J38: < upper | K38: 10 | L38: =$K38/INDEX('Indicator Master'!$N$4:$N$46,MATCH($A38,'Indicator Master'!$A$4:$A$46,0))*'Risk Bands (Config)'!$B$5 -> 33.333333 | M38: =IF($K38=INDEX('Indicator Master'!$N$4:$N$46,MATCH($A38,'Indicator Master'!$A$4:$A$46,0)),1,0) -> 0 | O38: Early warning — debtor days +15–30; early slowdown — collection lag or slow-moving receivables. | P38: 1) Review the debtor ageing. 2) Identify overdue/slow items. 3) Monitor. | Q38: RM + Credit Analyst | R38: =$A38&"|"&$K38 -> EWS-009|10
A39: EWS-009 | B39: Debtor days vs normal | C39: EWS | D39: Receivable days increasing sharply | E39: 3 | F39: 10-20 days | G39: Delta Days Range | H39: 10 | I39: 20 | J39: ≥ lower & < upper | K39: 20 | L39: =$K39/INDEX('Indicator Master'!$N$4:$N$46,MATCH($A39,'Indicator Master'!$A$4:$A$46,0))*'Risk Bands (Config)'!$B$5 -> 66.666667 | M39: =IF($K39=INDEX('Indicator Master'!$N$4:$N$46,MATCH($A39,'Indicator Master'!$A$4:$A$46,0)),1,0) -> 0 | O39: Elevated concern — debtor days +30–60; material tie-up of working capital in receivables. | P39: 1) Order a receivables audit. 2) Exclude >90-day receivables from DP. 3) Monitor monthly. | Q39: Credit Committee / Zonal Credit | R39: =$A39&"|"&$K39 -> EWS-009|20
A40: EWS-009 | B40: Debtor days vs normal | C40: EWS | D40: Receivable days increasing sharply | E40: 4 | F40: >20 days | G40: Delta Days Threshold | H40: 60 | J40: ≥ lower | K40: 30 | L40: =$K40/INDEX('Indicator Master'!$N$4:$N$46,MATCH($A40,'Indicator Master'!$A$4:$A$46,0))*'Risk Bands (Config)'!$B$5 -> 100 | M40: =IF($K40=INDEX('Indicator Master'!$N$4:$N$46,MATCH($A40,'Indicator Master'!$A$4:$A$46,0)),1,0) -> 1 | O40: Severe / critical — debtor days +60; severe — aged/blocked receivables, possible overstatement or non-moving stock. | P40: 1) Independent receivables audit; recompute DP. 2) Assess related-party / fictitious build-up. 3) Escalate to Credit; forensic if diversion suspected. | Q40: Credit Head / Risk | R40: =$A40&"|"&$K40 -> EWS-009|30
A41: EWS-010 | B41: Inventory days vs normal | C41: EWS | D41: Inventory holding period increasing | E41: 1 | F41: Within norm | G41: Delta Days Threshold | I41: 15 | J41: < upper | K41: 0 | L41: =$K41/INDEX('Indicator Master'!$N$4:$N$46,MATCH($A41,'Indicator Master'!$A$4:$A$46,0))*'Risk Bands (Config)'!$B$5 -> 0 | M41: =IF($K41=INDEX('Indicator Master'!$N$4:$N$46,MATCH($A41,'Indicator Master'!$A$4:$A$46,0)),1,0) -> 0 | O41: Normal — inventory days within norm; stock turning normally. | P41: No remedial action required. Continue routine monitoring at the standard review cycle and record the reading. | Q41: RM (routine) | R41: =$A41&"|"&$K41 -> EWS-010|0
...

Sheet Overall Score Engine
A1: Overall Score Engine (Live Calculator)
A2: Yellow cells are inputs. Overall = average of normalised scores of applicable indicators with valid data. Critical Override fires on (a) any Critical indicator at its trigger OR (b) any Critical Combination pair co-occurring (block below).
A4: Borrower Name | B4: Acme Textiles Pvt Ltd
A5: Assessment Date | B5: 31-Aug-2026
A7: Total Indicators | B7: =COUNTA($A$23:$A$65) -> 43
A8: Applicable Indicators | B8: =COUNTIF($F$23:$F$65,"Y") -> 39 | C8: Indicators relevant to this borrower (N/A excluded).
A9: Scored (valid data) | B9: =SUM($J$23:$J$65) -> 36 | C9: Applicable AND data available AND a raw score entered.
A10: Missing Data (applicable) | B10: =COUNTIFS($F$23:$F$65,"Y",$G$23:$G$65,"N") -> 3 | C10: Applicable but no data — EXCLUDED from the average (not treated as zero).
A11: Not Applicable (N/A) | B11: =COUNTIF($F$23:$F$65,"N") -> 4
A12: Data Coverage % | B12: =IF(B8=0,0,B9/B8*100) -> 92.307692 | C12: Reported separately; does NOT affect the Overall Score.
A13: Sum of Normalised (scored) | B13: =SUM($K$23:$K$65) -> 1020.8333
A14: Overall EWS Score | B14: =IF(B9=0,0,B13/B9) -> 28.356481 | C14: Average of normalised scores of applicable indicators with valid data.
A15: Numeric Risk Band | B15: =INDEX('Risk Bands (Config)'!$A$9:$A$13,MATCH(B14,'Risk Bands (Config)'!$D$9:$D$13,1)) -> Yellow | C15: Band implied by the Overall Score alone (before critical override).
A16: Critical Override Triggered? | B16: =IF(SUM($L$23:$L$65)+SUM($F$74:$F$76)>0,"YES","NO") -> YES | C16: YES if any CRITICAL indicator reaches the override trigger ('6. Risk Bands (Config)'!$B$6).
A17: Critical Indicators Fired | B17: =$M$65 -> EWS-026
A18: FINAL STATUS | B18: =IF(B16="YES","CRITICAL (Override)",IF(B12<'Risk Bands (Config)'!$B$16,"INSUFFICIENT DATA (band: "&B15&")",B15)) -> CRITICAL (Override)
A19: Final Interpretation | B19: =IF(B16="YES",INDEX('Risk Bands (Config)'!$E$9:$E$13,5),IF(B12<'Risk Bands (Config)'!$B$16,"Low data coverage — treat score as low-confidence; obtain missing data before acting.",INDEX('Risk Bands (Config)'!$E$9:$E$13,MATCH(B14,'Risk Bands (Config)'!$D$9:$D$13,1)))) -> Severe EWS / Immediate Intervention
A20: Traceability: FINAL STATUS ← Overall Score / Critical Override ← per-indicator Normalised ← Raw Score ← borrower Observed Value ← applicable threshold band.
A22: UID | B22: Indicator | C22: Module | D22: Critical | E22: Max Score | F22: Applicable (Y/N) | G22: Data Available (Y/N) | H22: Observed Value / Note | I22: Raw Score | J22: Scored Flag | K22: Normalised Score | L22: Critical Fire | M22: Crit Fire UID (helper) | N22: What it signals & likely drivers | O22: Remedial action plan (step-by-step) | P22: Primary owner
A23: EWS-001 | B23: Utilization % (outstanding / sanctioned) | C23: EWS | D23: =INDEX('Indicator Master'!$F$4:$F$46,MATCH($A23,'Indicator Master'!$A$4:$A$46,0)) -> No | E23: =INDEX('Indicator Master'!$N$4:$N$46,MATCH($A23,'Indicator Master'!$A$4:$A$46,0)) -> 30 | F23: Y | G23: Y | H23: CC utilisation >95% sustained for 30+ days → band '>95% for 30+ days' | I23: 30 | J23: =IF(AND($F23="Y",$G23="Y",ISNUMBER($I23)),1,0) -> 1 | K23: =IF($J23=1,$I23/$E23*'Risk Bands (Config)'!$B$5,"") -> 100 | L23: =IF(AND($D23="Yes",$J23=1,$I23/$E23*'Risk Bands (Config)'!$B$5>='Risk Bands (Config)'!$B$6),1,0) -> 0 | M23: =IF($L23=1,$A23,"") | N23: =IF($J23=1,IFERROR(INDEX('Scoring Engine (Rules)'!$O$5:$O$163,MATCH($A23&"|"&$I23,'Scoring Engine (Rules)'!$R$5:$R$163,0)),""),"") -> Severe / critical — utilisation above 95% for 30+ days; chronic over-reliance — possible inability to rotate WC, or diversion/ever-greening. | O23: =IF($J23=1,IFERROR(INDEX('Scoring Engine (Rules)'!$P$5:$P$163,MATCH($A23&"|"&$I23,'Scoring Engine (Rules)'!$R$5:$R$163,0)),""),"") -> 1) Restrict fresh drawals pending review. 2) Investigate diversion (routing gaps, ad-hoc pattern). 3) Full viability / limit-rationalisation review; escalate to Credit. | P23: =IF($J23=1,IFERROR(INDEX('Scoring Engine (Rules)'!$Q$5:$Q$163,MATCH($A23&"|"&$I23,'Scoring Engine (Rules)'!$R$5:$R$163,0)),""),"") -> Credit Head / Risk
A24: EWS-002 | B24: Count of ad-hoc limit requests (rolling 12m) | C24: EWS | D24: =INDEX('Indicator Master'!$F$4:$F$46,MATCH($A24,'Indicator Master'!$A$4:$A$46,0)) -> No | E24: =INDEX('Indicator Master'!$N$4:$N$46,MATCH($A24,'Indicator Master'!$A$4:$A$46,0)) -> 30 | F24: Y | G24: Y | H24: Matches band: 2 → band '2' | I24: 10 | J24: =IF(AND($F24="Y",$G24="Y",ISNUMBER($I24)),1,0) -> 1 | K24: =IF($J24=1,$I24/$E24*'Risk Bands (Config)'!$B$5,"") -> 33.333333 | L24: =IF(AND($D24="Yes",$J24=1,$I24/$E24*'Risk Bands (Config)'!$B$5>='Risk Bands (Config)'!$B$6),1,0) -> 0 | M24: =$M23&IF($L24=1,IF($M23="","",", ")&$A24,"") | N24: =IF($J24=1,IFERROR(INDEX('Scoring Engine (Rules)'!$O$5:$O$163,MATCH($A24&"|"&$I24,'Scoring Engine (Rules)'!$R$5:$R$163,0)),""),"") -> Early warning — two ad-hoc requests; occasional cash-flow mismatch. | O24: =IF($J24=1,IFERROR(INDEX('Scoring Engine (Rules)'!$P$5:$P$163,MATCH($A24&"|"&$I24,'Scoring Engine (Rules)'!$R$5:$R$163,0)),""),"") -> 1) Ascertain the reason for each request. 2) Check whether permanent WC is under-assessed. 3) Grant only against a documented need. | P24: =IF($J24=1,IFERROR(INDEX('Scoring Engine (Rules)'!$Q$5:$Q$163,MATCH($A24&"|"&$I24,'Scoring Engine (Rules)'!$R$5:$R$163,0)),""),"") -> RM + Credit Analyst
A25: EWS-003 | B25: Monthly sales vs credit summation | C25: EWS | D25: =INDEX('Indicator Master'!$F$4:$F$46,MATCH($A25,'Indicator Master'!$A$4:$A$46,0)) -> Yes | E25: =INDEX('Indicator Master'!$N$4:$N$46,MATCH($A25,'Indicator Master'!$A$4:$A$46,0)) -> 35 | F25: Y | G25: Y | H25: Operating-account credits down ~28% vs baseline → band '20-40% decline' | I25: 20 | J25: =IF(AND($F25="Y",$G25="Y",ISNUMBER($I25)),1,0) -> 1 | K25: =IF($J25=1,$I25/$E25*'Risk Bands (Config)'!$B$5,"") -> 57.142857 | L25: =IF(AND($D25="Yes",$J25=1,$I25/$E25*'Risk Bands (Config)'!$B$5>='Risk Bands (Config)'!$B$6),1,0) -> 0 | M25: =$M24&IF($L25=1,IF($M24="","",", ")&$A25,"") | N25: =IF($J25=1,IFERROR(INDEX('Scoring Engine (Rules)'!$O$5:$O$163,MATCH($A25&"|"&$I25,'Scoring Engine (Rules)'!$R$5:$R$163,0)),""),"") -> Elevated concern — credits down 20–40%; material drop — genuine sales fall or turnover being diverted elsewhere. | O25: =IF($J25=1,IFERROR(INDEX('Scoring Engine (Rules)'!$P$5:$P$163,MATCH($A25&"|"&$I25,'Scoring Engine (Rules)'!$R$5:$R$163,0)),""),"") -> 1) Stipulate proportionate turnover routing through the bank. 2) Verify sales via GST returns. 3) Monitor monthly credits vs sales. | P25: =IF($J25=1,IFERROR(INDEX('Scoring Engine (Rules)'!$Q$5:$Q$163,MATCH($A25&"|"&$I25,'Scoring Engine (Rules)'!$R$5:$R$163,0)),""),"") -> RM + Credit Analyst
A26: EWS-004 | B26: Payment Default Frequency | C26: EWS | D26: =INDEX('Indicator Master'!$F$4:$F$46,MATCH($A26,'Indicator Master'!$A$4:$A$46,0)) -> No | E26: =INDEX('Indicator Master'!$N$4:$N$46,MATCH($A26,'Indicator Master'!$A$4:$A$46,0)) -> 25 | F26: Y | G26: Y | H26: Matches band: 1 → band '1' | I26: 5 | J26: =IF(AND($F26="Y",$G26="Y",ISNUMBER($I26)),1,0) -> 1 | K26: =IF($J26=1,$I26/$E26*'Risk Bands (Config)'!$B$5,"") -> 20 | L26: =IF(AND($D26="Yes",$J26=1,$I26/$E26*'Risk Bands (Config)'!$B$5>='Risk Bands (Config)'!$B$6),1,0) -> 0 | M26: =$M25&IF($L26=1,IF($M25="","",", ")&$A26,"") | N26: =IF($J26=1,IFERROR(INDEX('Scoring Engine (Rules)'!$O$5:$O$163,MATCH($A26&"|"&$I26,'Scoring Engine (Rules)'!$R$5:$R$163,0)),""),"") -> Early warning — one conduct event; isolated slip, likely a timing mismatch. | O26: =IF($J26=1,IFERROR(INDEX('Scoring Engine (Rules)'!$P$5:$P$163,MATCH($A26&"|"&$I26,'Scoring Engine (Rules)'!$R$5:$R$163,0)),""),"") -> 1) Note the event and reason. 2) Caution the borrower informally. 3) Watch the next cycle. | P26: =IF($J26=1,IFERROR(INDEX('Scoring Engine (Rules)'!$Q$5:$Q$163,MATCH($A26&"|"&$I26,'Scoring Engine (Rules)'!$R$5:$R$163,0)),""),"") -> Relationship Manager (Branch)
A27: EWS-005 | B27: Repayment source classification | C27: EWS | D27: =INDEX('Indicator Master'!$F$4:$F$46,MATCH($A27,'Indicator Master'!$A$4:$A$46,0)) -> No | E27: =INDEX('Indicator Master'!$N$4:$N$46,MATCH($A27,'Indicator Master'!$A$4:$A$46,0)) -> 40 | F27: Y | G27: Y | H27: Matches band: Own operating cash flow → band 'Own operating cash flow' | I27: 0 | J27: =IF(AND($F27="Y",$G27="Y",ISNUMBER($I27)),1,0) -> 1 | K27: =IF($J27=1,$I27/$E27*'Risk Bands (Config)'!$B$5,"") -> 0 | L27: =IF(AND($D27="Yes",$J27=1,$I27/$E27*'Risk Bands (Config)'!$B$5>='Risk Bands (Config)'!$B$6),1,0) -> 0 | M27: =$M26&IF($L27=1,IF($M26="","",", ")&$A27,"") | N27: =IF($J27=1,IFERROR(INDEX('Scoring Engine (Rules)'!$O$5:$O$163,MATCH($A27&"|"&$I27,'Scoring Engine (Rules)'!$R$5:$R$163,0)),""),"") -> Normal — repayments from the borrower's own operating cash flows; healthy. | O27: =IF($J27=1,IFERROR(INDEX('Scoring Engine (Rules)'!$P$5:$P$163,MATCH($A27&"|"&$I27,'Scoring Engine (Rules)'!$R$5:$R$163,0)),""),"") -> No remedial action required. Continue routine monitoring at the standard review cycle and record the reading. | P27: =IF($J27=1,IFERROR(INDEX('Scoring Engine (Rules)'!$Q$5:$Q$163,MATCH($A27&"|"&$I27,'Scoring Engine (Rules)'!$R$5:$R$163,0)),""),"") -> RM (routine)
